Workbook

Sheet Input
A1: ......................................................................S......................................................................
A2: .............................................................................................................................................
A3: ......................................................................^......................................................................
A4: .............................................................................................................................................
A5: .....................................................................^.^.....................................................................
A6: .............................................................................................................................................
A7: ....................................................................^.^.^....................................................................
A8: .............................................................................................................................................
A9: ...................................................................^.....^...................................................................
A10: .............................................................................................................................................
A11: ..................................................................^.^.^.^.^..................................................................
A12: .............................................................................................................................................
... A142: .............................................................................................................................................

Sheet Q1.parsed
B1: 1 | C1: 2 | D1: 3 | E1: 4 | F1: 5 | G1: 6 | H1: 7 | I1: 8 | J1: 9 | K1: 10 | L1: 11 | M1: 12 | N1: 13 | O1: 14 | P1: 15 | Q1: 16 | R1: 17 | S1: 18 | T1: 19 | U1: 20 | V1: 21 | W1: 22 | X1: 23 | Y1: 24 | Z1: 25 | AA1: 26 | AB1: 27 | AC1: 28 | AD1: 29 | AE1: 30 | AF1: 31 | AG1: 32 | AH1: 33 | AI1: 34 | AJ1: 35 | AK1: 36 | AL1: 37 | AM1: 38 | AN1: 39 | AO1: 40 | AP1: 41 | AQ1: 42 | AR1: 43 | AS1: 44 | AT1: 45 | AU1: 46 | AV1: 47 | AW1: 48 | AX1: 49 | AY1: 50 | AZ1: 51 | BA1: 52 | BB1: 53 | BC1: 54 | BD1: 55 | BE1: 56 | BF1: 57 | BG1: 58 | BH1: 59 | BI1: 60 | BJ1: 61 | BK1: 62 | BL1: 63 | BM1: 64 | BN1: 65 | BO1: 66 | BP1: 67 | BQ1: 68 | BR1: 69 | BS1: 70 | BT1: 71 | BU1: 72 | BV1: 73 | BW1: 74 | BX1: 75 | BY1: 76 | BZ1: 77 | CA1: 78 | CB1: 79 | CC1: 80 | CD1: 81 | CE1: 82 | CF1: 83 | CG1: 84 | CH1: 85 | CI1: 86 | CJ1: 87 | CK1: 88 | CL1: 89 | CM1: 90 | CN1: 91 | CO1: 92 | CP1: 93 | CQ1: 94 | CR1: 95 | CS1: 96 | CT1: 97 | CU1: 98 | CV1: 99 | CW1: 100 | CX1: 101 | CY1: 102 | CZ1: 103 | DA1: 104 | DB1: 105 | DC1: 106 | DD1: 107 | DE1: 108 | DF1: 109 | DG1: 110 | DH1: 111 | DI1: 112 | DJ1: 113 | DK1: 114 | DL1: 115 | DM1: 116 | DN1: 117 | DO1: 118 | DP1: 119 | DQ1: 120 | DR1: 121 | DS1: 122 | DT1: 123 | DU1: 124 | DV1: 125 | DW1: 126 | DX1: 127 | DY1: 128 | DZ1: 129 | EA1: 130 | EB1: 131 | EC1: 132 | ED1: 133 | EE1: 134 | EF1: 135 | EG1: 136 | EH1: 137 | EI1: 138 | EJ1: 139 | EK1: 140 | EL1: 141
B2: =IF(B$1>LEN(Input!$A1), "", RIGHT(LEFT(Input!$A1, B$1), 1)) -> . | C2: =IF(C$1>LEN(Input!$A1), "", RIGHT(LEFT(Input!$A1, C$1), 1)) -> . | D2: =IF(D$1>LEN(Input!$A1), "", RIGHT(LEFT(Input!$A1, D$1), 1)) -> . | E2: =IF(E$1>LEN(Input!$A1), "", RIGHT(LEFT(Input!$A1, E$1), 1)) -> . | F2: =IF(F$1>LEN(Input!$A1), "", RIGHT(LEFT(Input!$A1, F$1), 1)) -> . | G2: =IF(G$1>LEN(Input!$A1), "", RIGHT(LEFT(Input!$A1, G$1), 1)) -> . | H2: =IF(H$1>LEN(Input!$A1), "", RIGHT(LEFT(Input!$A1, H$1), 1)) -> . | I2: =IF(I$1>LEN(Input!$A1), "", RIGHT(LEFT(Input!$A1, I$1), 1)) -> . | ... BS2: =IF(BS$1>LEN(Input!$A1), "", RIGHT(LEFT(Input!$A1, BS$1), 1)) -> . | BT2: | | BU2: =IF(BU$1>LEN(Input!$A1), "", RIGHT(LEFT(Input!$A1, BU$1), 1)) -> . | BV2: =IF(BV$1>LEN(Input!$A1), "", RIGHT(LEFT(Input!$A1, BV$1), 1)) -> . | BW2: =IF(BW$1>LEN(Input!$A1), "", RIGHT(LEFT(Input!$A1, BW$1), 1)) -> . | BX2: =IF(BX$1>LEN(Input!$A1), "", RIGHT(LEFT(Input!$A1, BX$1), 1)) -> . | BY2: =IF(BY$1>LEN(Input!$A1), "", RIGHT(LEFT(Input!$A1, BY$1), 1)) -> . | BZ2: =IF(BZ$1>LEN(Input!$A1), "", RIGHT(LEFT(Input!$A1, BZ$1), 1)) -> . | CA2: =IF(CA$1>LEN(Input!$A1), "", RIGHT(LEFT(Input!$A1, CA$1), 1)) -> . | CB2: =IF(CB$1>LEN(Input!$A1), "", RIGHT(LEFT(Input!$A1, CB$1), 1)) -> . | ... EL2: =IF(EL$1>LEN(Input!$A1), "", RIGHT(LEFT(Input!$A1, EL$1), 1)) -> .
B3: =IF(B$1>LEN(Input!$A2), "", RIGHT(LEFT(Input!$A2, B$1), 1)) -> . | C3: =IF(C$1>LEN(Input!$A2), "", RIGHT(LEFT(Input!$A2, C$1), 1)) -> . | D3: =IF(D$1>LEN(Input!$A2), "", RIGHT(LEFT(Input!$A2, D$1), 1)) -> . | E3: =IF(E$1>LEN(Input!$A2), "", RIGHT(LEFT(Input!$A2, E$1), 1)) -> . | F3: =IF(F$1>LEN(Input!$A2), "", RIGHT(LEFT(Input!$A2, F$1), 1)) -> . | G3: =IF(G$1>LEN(Input!$A2), "", RIGHT(LEFT(Input!$A2, G$1), 1)) -> . | H3: =IF(H$1>LEN(Input!$A2), "", RIGHT(LEFT(Input!$A2, H$1), 1)) -> . | I3: =IF(I$1>LEN(Input!$A2), "", RIGHT(LEFT(Input!$A2, I$1), 1)) -> . | ... EL3: =IF(EL$1>LEN(Input!$A2), "", RIGHT(LEFT(Input!$A2, EL$1), 1)) -> .
B4: =IF(B$1>LEN(Input!$A3), "", RIGHT(LEFT(Input!$A3, B$1), 1)) -> . | C4: =IF(C$1>LEN(Input!$A3), "", RIGHT(LEFT(Input!$A3, C$1), 1)) -> . | D4: =IF(D$1>LEN(Input!$A3), "", RIGHT(LEFT(Input!$A3, D$1), 1)) -> . | E4: =IF(E$1>LEN(Input!$A3), "", RIGHT(LEFT(Input!$A3, E$1), 1)) -> . | F4: =IF(F$1>LEN(Input!$A3), "", RIGHT(LEFT(Input!$A3, F$1), 1)) -> . | G4: =IF(G$1>LEN(Input!$A3), "", RIGHT(LEFT(Input!$A3, G$1), 1)) -> . | H4: =IF(H$1>LEN(Input!$A3), "", RIGHT(LEFT(Input!$A3, H$1), 1)) -> . | I4: =IF(I$1>LEN(Input!$A3), "", RIGHT(LEFT(Input!$A3, I$1), 1)) -> . | ... EL4: =IF(EL$1>LEN(Input!$A3), "", RIGHT(LEFT(Input!$A3, EL$1), 1)) -> .
B5: =IF(B$1>LEN(Input!$A4), "", RIGHT(LEFT(Input!$A4, B$1), 1)) -> . | C5: =IF(C$1>LEN(Input!$A4), "", RIGHT(LEFT(Input!$A4, C$1), 1)) -> . | D5: =IF(D$1>LEN(Input!$A4), "", RIGHT(LEFT(Input!$A4, D$1), 1)) -> . | E5: =IF(E$1>LEN(Input!$A4), "", RIGHT(LEFT(Input!$A4, E$1), 1)) -> . | F5: =IF(F$1>LEN(Input!$A4), "", RIGHT(LEFT(Input!$A4, F$1), 1)) -> . | G5: =IF(G$1>LEN(Input!$A4), "", RIGHT(LEFT(Input!$A4, G$1), 1)) -> . | H5: =IF(H$1>LEN(Input!$A4), "", RIGHT(LEFT(Input!$A4, H$1), 1)) -> . | I5: =IF(I$1>LEN(Input!$A4), "", RIGHT(LEFT(Input!$A4, I$1), 1)) -> . | ... EL5: =IF(EL$1>LEN(Input!$A4), "", RIGHT(LEFT(Input!$A4, EL$1), 1)) -> .
B6: =IF(B$1>LEN(Input!$A5), "", RIGHT(LEFT(Input!$A5, B$1), 1)) -> . | C6: =IF(C$1>LEN(Input!$A5), "", RIGHT(LEFT(Input!$A5, C$1), 1)) -> . | D6: =IF(D$1>LEN(Input!$A5), "", RIGHT(LEFT(Input!$A5, D$1), 1)) -> . | E6: =IF(E$1>LEN(Input!$A5), "", RIGHT(LEFT(Input!$A5, E$1), 1)) -> . | F6: =IF(F$1>LEN(Input!$A5), "", RIGHT(LEFT(Input!$A5, F$1), 1)) -> . | G6: =IF(G$1>LEN(Input!$A5), "", RIGHT(LEFT(Input!$A5, G$1), 1)) -> . | H6: =IF(H$1>LEN(Input!$A5), "", RIGHT(LEFT(Input!$A5, H$1), 1)) -> . | I6: =IF(I$1>LEN(Input!$A5), "", RIGHT(LEFT(Input!$A5, I$1), 1)) -> . | ... EL6: =IF(EL$1>LEN(Input!$A5), "", RIGHT(LEFT(Input!$A5, EL$1), 1)) -> .
B7: =IF(B$1>LEN(Input!$A6), "", RIGHT(LEFT(Input!$A6, B$1), 1)) -> . | C7: =IF(C$1>LEN(Input!$A6), "", RIGHT(LEFT(Input!$A6, C$1), 1)) -> . | D7: =IF(D$1>LEN(Input!$A6), "", RIGHT(LEFT(Input!$A6, D$1), 1)) -> . | E7: =IF(E$1>LEN(Input!$A6), "", RIGHT(LEFT(Input!$A6, E$1), 1)) -> . | F7: =IF(F$1>LEN(Input!$A6), "", RIGHT(LEFT(Input!$A6, F$1), 1)) -> . | G7: =IF(G$1>LEN(Input!$A6), "", RIGHT(LEFT(Input!$A6, G$1), 1)) -> . | H7: =IF(H$1>LEN(Input!$A6), "", RIGHT(LEFT(Input!$A6, H$1), 1)) -> . | I7: =IF(I$1>LEN(Input!$A6), "", RIGHT(LEFT(Input!$A6, I$1), 1)) -> . | ... EL7: =IF(EL$1>LEN(Input!$A6), "", RIGHT(LEFT(Input!$A6, EL$1), 1)) -> .
B8: =IF(B$1>LEN(Input!$A7), "", RIGHT(LEFT(Input!$A7, B$1), 1)) -> . | C8: =IF(C$1>LEN(Input!$A7), "", RIGHT(LEFT(Input!$A7, C$1), 1)) -> . | D8: =IF(D$1>LEN(Input!$A7), "", RIGHT(LEFT(Input!$A7, D$1), 1)) -> . | E8: =IF(E$1>LEN(Input!$A7), "", RIGHT(LEFT(Input!$A7, E$1), 1)) -> . | F8: =IF(F$1>LEN(Input!$A7), "", RIGHT(LEFT(Input!$A7, F$1), 1)) -> . | G8: =IF(G$1>LEN(Input!$A7), "", RIGHT(LEFT(Input!$A7, G$1), 1)) -> . | H8: =IF(H$1>LEN(Input!$A7), "", RIGHT(LEFT(Input!$A7, H$1), 1)) -> . | I8: =IF(I$1>LEN(Input!$A7), "", RIGHT(LEFT(Input!$A7, I$1), 1)) -> . | ... EL8: =IF(EL$1>LEN(Input!$A7), "", RIGHT(LEFT(Input!$A7, EL$1), 1)) -> .
B9: =IF(B$1>LEN(Input!$A8), "", RIGHT(LEFT(Input!$A8, B$1), 1)) -> . | C9: =IF(C$1>LEN(Input!$A8), "", RIGHT(LEFT(Input!$A8, C$1), 1)) -> . | D9: =IF(D$1>LEN(Input!$A8), "", RIGHT(LEFT(Input!$A8, D$1), 1)) -> . | E9: =IF(E$1>LEN(Input!$A8), "", RIGHT(LEFT(Input!$A8, E$1), 1)) -> . | F9: =IF(F$1>LEN(Input!$A8), "", RIGHT(LEFT(Input!$A8, F$1), 1)) -> . | G9: =IF(G$1>LEN(Input!$A8), "", RIGHT(LEFT(Input!$A8, G$1), 1)) -> . | H9: =IF(H$1>LEN(Input!$A8), "", RIGHT(LEFT(Input!$A8, H$1), 1)) -> . | I9: =IF(I$1>LEN(Input!$A8), "", RIGHT(LEFT(Input!$A8, I$1), 1)) -> . | ... EL9: =IF(EL$1>LEN(Input!$A8), "", RIGHT(LEFT(Input!$A8, EL$1), 1)) -> .
B10: =IF(B$1>LEN(Input!$A9), "", RIGHT(LEFT(Input!$A9, B$1), 1)) -> . | C10: =IF(C$1>LEN(Input!$A9), "", RIGHT(LEFT(Input!$A9, C$1), 1)) -> . | D10: =IF(D$1>LEN(Input!$A9), "", RIGHT(LEFT(Input!$A9, D$1), 1)) -> . | E10: =IF(E$1>LEN(Input!$A9), "", RIGHT(LEFT(Input!$A9, E$1), 1)) -> . | F10: =IF(F$1>LEN(Input!$A9), "", RIGHT(LEFT(Input!$A9, F$1), 1)) -> . | G10: =IF(G$1>LEN(Input!$A9), "", RIGHT(LEFT(Input!$A9, G$1), 1)) -> . | H10: =IF(H$1>LEN(Input!$A9), "", RIGHT(LEFT(Input!$A9, H$1), 1)) -> . | I10: =IF(I$1>LEN(Input!$A9), "", RIGHT(LEFT(Input!$A9, I$1), 1)) -> . | ... EL10: =IF(EL$1>LEN(Input!$A9), "", RIGHT(LEFT(Input!$A9, EL$1), 1)) -> .
B11: =IF(B$1>LEN(Input!$A10), "", RIGHT(LEFT(Input!$A10, B$1), 1)) -> . | C11: =IF(C$1>LEN(Input!$A10), "", RIGHT(LEFT(Input!$A10, C$1), 1)) -> . | D11: =IF(D$1>LEN(Input!$A10), "", RIGHT(LEFT(Input!$A10, D$1), 1)) -> . | E11: =IF(E$1>LEN(Input!$A10), "", RIGHT(LEFT(Input!$A10, E$1), 1)) -> . | F11: =IF(F$1>LEN(Input!$A10), "", RIGHT(LEFT(Input!$A10, F$1), 1)) -> . | G11: =IF(G$1>LEN(Input!$A10), "", RIGHT(LEFT(Input!$A10, G$1), 1)) -> . | H11: =IF(H$1>LEN(Input!$A10), "", RIGHT(LEFT(Input!$A10, H$1), 1)) -> . | I11: =IF(I$1>LEN(Input!$A10), "", RIGHT(LEFT(Input!$A10, I$1), 1)) -> . | ... EL11: =IF(EL$1>LEN(Input!$A10), "", RIGHT(LEFT(Input!$A10, EL$1), 1)) -> .
B12: =IF(B$1>LEN(Input!$A11), "", RIGHT(LEFT(Input!$A11, B$1), 1)) -> . | C12: =IF(C$1>LEN(Input!$A11), "", RIGHT(LEFT(Input!$A11, C$1), 1)) -> . | D12: =IF(D$1>LEN(Input!$A11), "", RIGHT(LEFT(Input!$A11, D$1), 1)) -> . | E12: =IF(E$1>LEN(Input!$A11), "", RIGHT(LEFT(Input!$A11, E$1), 1)) -> . | F12: =IF(F$1>LEN(Input!$A11), "", RIGHT(LEFT(Input!$A11, F$1), 1)) -> . | G12: =IF(G$1>LEN(Input!$A11), "", RIGHT(LEFT(Input!$A11, G$1), 1)) -> . | H12: =IF(H$1>LEN(Input!$A11), "", RIGHT(LEFT(Input!$A11, H$1), 1)) -> . | I12: =IF(I$1>LEN(Input!$A11), "", RIGHT(LEFT(Input!$A11, I$1), 1)) -> . | ... EL12: =IF(EL$1>LEN(Input!$A11), "", RIGHT(LEFT(Input!$A11, EL$1), 1)) -> .
B13: =IF(B$1>LEN(Input!$A12), "", RIGHT(LEFT(Input!$A12, B$1), 1)) -> . | C13: =IF(C$1>LEN(Input!$A12), "", RIGHT(LEFT(Input!$A12, C$1), 1)) -> . | D13: =IF(D$1>LEN(Input!$A12), "", RIGHT(LEFT(Input!$A12, D$1), 1)) -> . | E13: =IF(E$1>LEN(Input!$A12), "", RIGHT(LEFT(Input!$A12, E$1), 1)) -> . | F13: =IF(F$1>LEN(Input!$A12), "", RIGHT(LEFT(Input!$A12, F$1), 1)) -> . | G13: =IF(G$1>LEN(Input!$A12), "", RIGHT(LEFT(Input!$A12, G$1), 1)) -> . | H13: =IF(H$1>LEN(Input!$A12), "", RIGHT(LEFT(Input!$A12, H$1), 1)) -> . | I13: =IF(I$1>LEN(Input!$A12), "", RIGHT(LEFT(Input!$A12, I$1), 1)) -> . | ... EL13: =IF(EL$1>LEN(Input!$A12), "", RIGHT(LEFT(Input!$A12, EL$1), 1)) -> .
B14: =IF(B$1>LEN(Input!$A13), "", RIGHT(LEFT(Input!$A13, B$1), 1)) -> . | C14: =IF(C$1>LEN(Input!$A13), "", RIGHT(LEFT(Input!$A13, C$1), 1)) -> . | D14: =IF(D$1>LEN(Input!$A13), "", RIGHT(LEFT(Input!$A13, D$1), 1)) -> . | E14: =IF(E$1>LEN(Input!$A13), "", RIGHT(LEFT(Input!$A13, E$1), 1)) -> . | F14: =IF(F$1>LEN(Input!$A13), "", RIGHT(LEFT(Input!$A13, F$1), 1)) -> . | G14: =IF(G$1>LEN(Input!$A13), "", RIGHT(LEFT(Input!$A13, G$1), 1)) -> . | H14: =IF(H$1>LEN(Input!$A13), "", RIGHT(LEFT(Input!$A13, H$1), 1)) -> . | I14: =IF(I$1>LEN(Input!$A13), "", RIGHT(LEFT(Input!$A13, I$1), 1)) -> . | ... EL14: =IF(EL$1>LEN(Input!$A13), "", RIGHT(LEFT(Input!$A13, EL$1), 1)) -> .
... B143: =IF(B$1>LEN(Input!$A142), "", RIGHT(LEFT(Input!$A142, B$1), 1)) -> . | C143: =IF(C$1>LEN(Input!$A142), "", RIGHT(LEFT(Input!$A142, C$1), 1)) -> . | D143: =IF(D$1>LEN(Input!$A142), "", RIGHT(LEFT(Input!$A142, D$1), 1)) -> . | E143: =IF(E$1>LEN(Input!$A142), "", RIGHT(LEFT(Input!$A142, E$1), 1)) -> . | F143: =IF(F$1>LEN(Input!$A142), "", RIGHT(LEFT(Input!$A142, F$1), 1)) -> . | G143: =IF(G$1>LEN(Input!$A142), "", RIGHT(LEFT(Input!$A142, G$1), 1)) -> . | H143: =IF(H$1>LEN(Input!$A142), "", RIGHT(LEFT(Input!$A142, H$1), 1)) -> . | I143: =IF(I$1>LEN(Input!$A142), "", RIGHT(LEFT(Input!$A142, I$1), 1)) -> . | ... EL143: =IF(EL$1>LEN(Input!$A142), "", RIGHT(LEFT(Input!$A142, EL$1), 1)) -> .

Sheet Q1.splits
B1: If self is . and above is |, then |
B2: If self is . and right is ^ and above right is | or left is ^ and above left is | then |
B3: else
B4: =IF('Q1.parsed'!B2=".", IF(OR(B3="|", AND('Q1.parsed'!C2="^", C3="|"), AND('Q1.parsed'!A2="^", A3="|")), "|", 'Q1.parsed'!B2), 'Q1.parsed'!B2) -> . | C4: =IF('Q1.parsed'!C2=".", IF(OR(C3="|", AND('Q1.parsed'!D2="^", D3="|"), AND('Q1.parsed'!B2="^", B3="|")), "|", 'Q1.parsed'!C2), 'Q1.parsed'!C2) -> . | D4: =IF('Q1.parsed'!D2=".", IF(OR(D3="|", AND('Q1.parsed'!E2="^", E3="|"), AND('Q1.parsed'!C2="^", C3="|")), "|", 'Q1.parsed'!D2), 'Q1.parsed'!D2) -> . | E4: =IF('Q1.parsed'!E2=".", IF(OR(E3="|", AND('Q1.parsed'!F2="^", F3="|"), AND('Q1.parsed'!D2="^", D3="|")), "|", 'Q1.parsed'!E2), 'Q1.parsed'!E2) -> . | F4: =IF('Q1.parsed'!F2=".", IF(OR(F3="|", AND('Q1.parsed'!G2="^", G3="|"), AND('Q1.parsed'!E2="^", E3="|")), "|", 'Q1.parsed'!F2), 'Q1.parsed'!F2) -> . | G4: =IF('Q1.parsed'!G2=".", IF(OR(G3="|", AND('Q1.parsed'!H2="^", H3="|"), AND('Q1.parsed'!F2="^", F3="|")), "|", 'Q1.parsed'!G2), 'Q1.parsed'!G2) -> . | H4: =IF('Q1.parsed'!H2=".", IF(OR(H3="|", AND('Q1.parsed'!I2="^", I3="|"), AND('Q1.parsed'!G2="^", G3="|")), "|", 'Q1.parsed'!H2), 'Q1.parsed'!H2) -> . | I4: =IF('Q1.parsed'!I2=".", IF(OR(I3="|", AND('Q1.parsed'!J2="^", J3="|"), AND('Q1.parsed'!H2="^", H3="|")), "|", 'Q1.parsed'!I2), 'Q1.parsed'!I2) -> . | ... EL4: =IF('Q1.parsed'!EL2=".", IF(OR(EL3="|", AND('Q1.parsed'!EM2="^", EM3="|"), AND('Q1.parsed'!EK2="^", EK3="|")), "|", 'Q1.parsed'!EL2), 'Q1.parsed'!EL2) -> .
B5: =IF('Q1.parsed'!B3=".", IF(OR(B4="|", AND('Q1.parsed'!C3="^", C4="|"), AND('Q1.parsed'!A3="^", A4="|")), "|", 'Q1.parsed'!B3), 'Q1.parsed'!B3) -> . | C5: =IF('Q1.parsed'!C3=".", IF(OR(C4="|", AND('Q1.parsed'!D3="^", D4="|"), AND('Q1.parsed'!B3="^", B4="|")), "|", 'Q1.parsed'!C3), 'Q1.parsed'!C3) -> . | D5: =IF('Q1.parsed'!D3=".", IF(OR(D4="|", AND('Q1.parsed'!E3="^", E4="|"), AND('Q1.parsed'!C3="^", C4="|")), "|", 'Q1.parsed'!D3), 'Q1.parsed'!D3) -> . | E5: =IF('Q1.parsed'!E3=".", IF(OR(E4="|", AND('Q1.parsed'!F3="^", F4="|"), AND('Q1.parsed'!D3="^", D4="|")), "|", 'Q1.parsed'!E3), 'Q1.parsed'!E3) -> . | F5: =IF('Q1.parsed'!F3=".", IF(OR(F4="|", AND('Q1.parsed'!G3="^", G4="|"), AND('Q1.parsed'!E3="^", E4="|")), "|", 'Q1.parsed'!F3), 'Q1.parsed'!F3) -> . | G5: =IF('Q1.parsed'!G3=".", IF(OR(G4="|", AND('Q1.parsed'!H3="^", H4="|"), AND('Q1.parsed'!F3="^", F4="|")), "|", 'Q1.parsed'!G3), 'Q1.parsed'!G3) -> . | H5: =IF('Q1.parsed'!H3=".", IF(OR(H4="|", AND('Q1.parsed'!I3="^", I4="|"), AND('Q1.parsed'!G3="^", G4="|")), "|", 'Q1.parsed'!H3), 'Q1.parsed'!H3) -> . | I5: =IF('Q1.parsed'!I3=".", IF(OR(I4="|", AND('Q1.parsed'!J3="^", J4="|"), AND('Q1.parsed'!H3="^", H4="|")), "|", 'Q1.parsed'!I3), 'Q1.parsed'!I3) -> . | ... EL5: =IF('Q1.parsed'!EL3=".", IF(OR(EL4="|", AND('Q1.parsed'!EM3="^", EM4="|"), AND('Q1.parsed'!EK3="^", EK4="|")), "|", 'Q1.parsed'!EL3), 'Q1.parsed'!EL3) -> .
B6: =IF('Q1.parsed'!B4=".", IF(OR(B5="|", AND('Q1.parsed'!C4="^", C5="|"), AND('Q1.parsed'!A4="^", A5="|")), "|", 'Q1.parsed'!B4), 'Q1.parsed'!B4) -> . | C6: =IF('Q1.parsed'!C4=".", IF(OR(C5="|", AND('Q1.parsed'!D4="^", D5="|"), AND('Q1.parsed'!B4="^", B5="|")), "|", 'Q1.parsed'!C4), 'Q1.parsed'!C4) -> . | D6: =IF('Q1.parsed'!D4=".", IF(OR(D5="|", AND('Q1.parsed'!E4="^", E5="|"), AND('Q1.parsed'!C4="^", C5="|")), "|", 'Q1.parsed'!D4), 'Q1.parsed'!D4) -> . | E6: =IF('Q1.parsed'!E4=".", IF(OR(E5="|", AND('Q1.parsed'!F4="^", F5="|"), AND('Q1.parsed'!D4="^", D5="|")), "|", 'Q1.parsed'!E4), 'Q1.parsed'!E4) -> . | F6: =IF('Q1.parsed'!F4=".", IF(OR(F5="|", AND('Q1.parsed'!G4="^", G5="|"), AND('Q1.parsed'!E4="^", E5="|")), "|", 'Q1.parsed'!F4), 'Q1.parsed'!F4) -> . | G6: =IF('Q1.parsed'!G4=".", IF(OR(G5="|", AND('Q1.parsed'!H4="^", H5="|"), AND('Q1.parsed'!F4="^", F5="|")), "|", 'Q1.parsed'!G4), 'Q1.parsed'!G4) -> . | H6: =IF('Q1.parsed'!H4=".", IF(OR(H5="|", AND('Q1.parsed'!I4="^", I5="|"), AND('Q1.parsed'!G4="^", G5="|")), "|", 'Q1.parsed'!H4), 'Q1.parsed'!H4) -> . | I6: =IF('Q1.parsed'!I4=".", IF(OR(I5="|", AND('Q1.parsed'!J4="^", J5="|"), AND('Q1.parsed'!H4="^", H5="|")), "|", 'Q1.parsed'!I4), 'Q1.parsed'!I4) -> . | ... EL6: =IF('Q1.parsed'!EL4=".", IF(OR(EL5="|", AND('Q1.parsed'!EM4="^", EM5="|"), AND('Q1.parsed'!EK4="^", EK5="|")), "|", 'Q1.parsed'!EL4), 'Q1.parsed'!EL4) -> .
B7: =IF('Q1.parsed'!B5=".", IF(OR(B6="|", AND('Q1.parsed'!C5="^", C6="|"), AND('Q1.parsed'!A5="^", A6="|")), "|", 'Q1.parsed'!B5), 'Q1.parsed'!B5) -> . | C7: =IF('Q1.parsed'!C5=".", IF(OR(C6="|", AND('Q1.parsed'!D5="^", D6="|"), AND('Q1.parsed'!B5="^", B6="|")), "|", 'Q1.parsed'!C5), 'Q1.parsed'!C5) -> . | D7: =IF('Q1.parsed'!D5=".", IF(OR(D6="|", AND('Q1.parsed'!E5="^", E6="|"), AND('Q1.parsed'!C5="^", C6="|")), "|", 'Q1.parsed'!D5), 'Q1.parsed'!D5) -> . | E7: =IF('Q1.parsed'!E5=".", IF(OR(E6="|", AND('Q1.parsed'!F5="^", F6="|"), AND('Q1.parsed'!D5="^", D6="|")), "|", 'Q1.parsed'!E5), 'Q1.parsed'!E5) -> . | F7: =IF('Q1.parsed'!F5=".", IF(OR(F6="|", AND('Q1.parsed'!G5="^", G6="|"), AND('Q1.parsed'!E5="^", E6="|")), "|", 'Q1.parsed'!F5), 'Q1.parsed'!F5) -> . | G7: =IF('Q1.parsed'!G5=".", IF(OR(G6="|", AND('Q1.parsed'!H5="^", H6="|"), AND('Q1.parsed'!F5="^", F6="|")), "|", 'Q1.parsed'!G5), 'Q1.parsed'!G5) -> . | H7: =IF('Q1.parsed'!H5=".", IF(OR(H6="|", AND('Q1.parsed'!I5="^", I6="|"), AND('Q1.parsed'!G5="^", G6="|")), "|", 'Q1.parsed'!H5), 'Q1.parsed'!H5) -> . | I7: =IF('Q1.parsed'!I5=".", IF(OR(I6="|", AND('Q1.parsed'!J5="^", J6="|"), AND('Q1.parsed'!H5="^", H6="|")), "|", 'Q1.parsed'!I5), 'Q1.parsed'!I5) -> . | ... EL7: =IF('Q1.parsed'!EL5=".", IF(OR(EL6="|", AND('Q1.parsed'!EM5="^", EM6="|"), AND('Q1.parsed'!EK5="^", EK6="|")), "|", 'Q1.parsed'!EL5), 'Q1.parsed'!EL5) -> .
B8: =IF('Q1.parsed'!B6=".", IF(OR(B7="|", AND('Q1.parsed'!C6="^", C7="|"), AND('Q1.parsed'!A6="^", A7="|")), "|", 'Q1.parsed'!B6), 'Q1.parsed'!B6) -> . | C8: =IF('Q1.parsed'!C6=".", IF(OR(C7="|", AND('Q1.parsed'!D6="^", D7="|"), AND('Q1.parsed'!B6="^", B7="|")), "|", 'Q1.parsed'!C6), 'Q1.parsed'!C6) -> . | D8: =IF('Q1.parsed'!D6=".", IF(OR(D7="|", AND('Q1.parsed'!E6="^", E7="|"), AND('Q1.parsed'!C6="^", C7="|")), "|", 'Q1.parsed'!D6), 'Q1.parsed'!D6) -> . | E8: =IF('Q1.parsed'!E6=".", IF(OR(E7="|", AND('Q1.parsed'!F6="^", F7="|"), AND('Q1.parsed'!D6="^", D7="|")), "|", 'Q1.parsed'!E6), 'Q1.parsed'!E6) -> . | F8: =IF('Q1.parsed'!F6=".", IF(OR(F7="|", AND('Q1.parsed'!G6="^", G7="|"), AND('Q1.parsed'!E6="^", E7="|")), "|", 'Q1.parsed'!F6), 'Q1.parsed'!F6) -> . | G8: =IF('Q1.parsed'!G6=".", IF(OR(G7="|", AND('Q1.parsed'!H6="^", H7="|"), AND('Q1.parsed'!F6="^", F7="|")), "|", 'Q1.parsed'!G6), 'Q1.parsed'!G6) -> . | H8: =IF('Q1.parsed'!H6=".", IF(OR(H7="|", AND('Q1.parsed'!I6="^", I7="|"), AND('Q1.parsed'!G6="^", G7="|")), "|", 'Q1.parsed'!H6), 'Q1.parsed'!H6) -> . | I8: =IF('Q1.parsed'!I6=".", IF(OR(I7="|", AND('Q1.parsed'!J6="^", J7="|"), AND('Q1.parsed'!H6="^", H7="|")), "|", 'Q1.parsed'!I6), 'Q1.parsed'!I6) -> . | ... EL8: =IF('Q1.parsed'!EL6=".", IF(OR(EL7="|", AND('Q1.parsed'!EM6="^", EM7="|"), AND('Q1.parsed'!EK6="^", EK7="|")), "|", 'Q1.parsed'!EL6), 'Q1.parsed'!EL6) -> .
B9: =IF('Q1.parsed'!B7=".", IF(OR(B8="|", AND('Q1.parsed'!C7="^", C8="|"), AND('Q1.parsed'!A7="^", A8="|")), "|", 'Q1.parsed'!B7), 'Q1.parsed'!B7) -> . | C9: =IF('Q1.parsed'!C7=".", IF(OR(C8="|", AND('Q1.parsed'!D7="^", D8="|"), AND('Q1.parsed'!B7="^", B8="|")), "|", 'Q1.parsed'!C7), 'Q1.parsed'!C7) -> . | D9: =IF('Q1.parsed'!D7=".", IF(OR(D8="|", AND('Q1.parsed'!E7="^", E8="|"), AND('Q1.parsed'!C7="^", C8="|")), "|", 'Q1.parsed'!D7), 'Q1.parsed'!D7) -> . | E9: =IF('Q1.parsed'!E7=".", IF(OR(E8="|", AND('Q1.parsed'!F7="^", F8="|"), AND('Q1.parsed'!D7="^", D8="|")), "|", 'Q1.parsed'!E7), 'Q1.parsed'!E7) -> . | F9: =IF('Q1.parsed'!F7=".", IF(OR(F8="|", AND('Q1.parsed'!G7="^", G8="|"), AND('Q1.parsed'!E7="^", E8="|")), "|", 'Q1.parsed'!F7), 'Q1.parsed'!F7) -> . | G9: =IF('Q1.parsed'!G7=".", IF(OR(G8="|", AND('Q1.parsed'!H7="^", H8="|"), AND('Q1.parsed'!F7="^", F8="|")), "|", 'Q1.parsed'!G7), 'Q1.parsed'!G7) -> . | H9: =IF('Q1.parsed'!H7=".", IF(OR(H8="|", AND('Q1.parsed'!I7="^", I8="|"), AND('Q1.parsed'!G7="^", G8="|")), "|", 'Q1.parsed'!H7), 'Q1.parsed'!H7) -> . | I9: =IF('Q1.parsed'!I7=".", IF(OR(I8="|", AND('Q1.parsed'!J7="^", J8="|"), AND('Q1.parsed'!H7="^", H8="|")), "|", 'Q1.parsed'!I7), 'Q1.parsed'!I7) -> . | ... EL9: =IF('Q1.parsed'!EL7=".", IF(OR(EL8="|", AND('Q1.parsed'!EM7="^", EM8="|"), AND('Q1.parsed'!EK7="^", EK8="|")), "|", 'Q1.parsed'!EL7), 'Q1.parsed'!EL7) -> .
B10: =IF('Q1.parsed'!B8=".", IF(OR(B9="|", AND('Q1.parsed'!C8="^", C9="|"), AND('Q1.parsed'!A8="^", A9="|")), "|", 'Q1.parsed'!B8), 'Q1.parsed'!B8) -> . | C10: =IF('Q1.parsed'!C8=".", IF(OR(C9="|", AND('Q1.parsed'!D8="^", D9="|"), AND('Q1.parsed'!B8="^", B9="|")), "|", 'Q1.parsed'!C8), 'Q1.parsed'!C8) -> . | D10: =IF('Q1.parsed'!D8=".", IF(OR(D9="|", AND('Q1.parsed'!E8="^", E9="|"), AND('Q1.parsed'!C8="^", C9="|")), "|", 'Q1.parsed'!D8), 'Q1.parsed'!D8) -> . | E10: =IF('Q1.parsed'!E8=".", IF(OR(E9="|", AND('Q1.parsed'!F8="^", F9="|"), AND('Q1.parsed'!D8="^", D9="|")), "|", 'Q1.parsed'!E8), 'Q1.parsed'!E8) -> . | F10: =IF('Q1.parsed'!F8=".", IF(OR(F9="|", AND('Q1.parsed'!G8="^", G9="|"), AND('Q1.parsed'!E8="^", E9="|")), "|", 'Q1.parsed'!F8), 'Q1.parsed'!F8) -> . | G10: =IF('Q1.parsed'!G8=".", IF(OR(G9="|", AND('Q1.parsed'!H8="^", H9="|"), AND('Q1.parsed'!F8="^", F9="|")), "|", 'Q1.parsed'!G8), 'Q1.parsed'!G8) -> . | H10: =IF('Q1.parsed'!H8=".", IF(OR(H9="|", AND('Q1.parsed'!I8="^", I9="|"), AND('Q1.parsed'!G8="^", G9="|")), "|", 'Q1.parsed'!H8), 'Q1.parsed'!H8) -> . | I10: =IF('Q1.parsed'!I8=".", IF(OR(I9="|", AND('Q1.parsed'!J8="^", J9="|"), AND('Q1.parsed'!H8="^", H9="|")), "|", 'Q1.parsed'!I8), 'Q1.parsed'!I8) -> . | ... EL10: =IF('Q1.parsed'!EL8=".", IF(OR(EL9="|", AND('Q1.parsed'!EM8="^", EM9="|"), AND('Q1.parsed'!EK8="^", EK9="|")), "|", 'Q1.parsed'!EL8), 'Q1.parsed'!EL8) -> .
B11: =IF('Q1.parsed'!B9=".", IF(OR(B10="|", AND('Q1.parsed'!C9="^", C10="|"), AND('Q1.parsed'!A9="^", A10="|")), "|", 'Q1.parsed'!B9), 'Q1.parsed'!B9) -> . | C11: =IF('Q1.parsed'!C9=".", IF(OR(C10="|", AND('Q1.parsed'!D9="^", D10="|"), AND('Q1.parsed'!B9="^", B10="|")), "|", 'Q1.parsed'!C9), 'Q1.parsed'!C9) -> . | D11: =IF('Q1.parsed'!D9=".", IF(OR(D10="|", AND('Q1.parsed'!E9="^", E10="|"), AND('Q1.parsed'!C9="^", C10="|")), "|", 'Q1.parsed'!D9), 'Q1.parsed'!D9) -> . | E11: =IF('Q1.parsed'!E9=".", IF(OR(E10="|", AND('Q1.parsed'!F9="^", F10="|"), AND('Q1.parsed'!D9="^", D10="|")), "|", 'Q1.parsed'!E9), 'Q1.parsed'!E9) -> . | F11: =IF('Q1.parsed'!F9=".", IF(OR(F10="|", AND('Q1.parsed'!G9="^", G10="|"), AND('Q1.parsed'!E9="^", E10="|")), "|", 'Q1.parsed'!F9), 'Q1.parsed'!F9) -> . | G11: =IF('Q1.parsed'!G9=".", IF(OR(G10="|", AND('Q1.parsed'!H9="^", H10="|"), AND('Q1.parsed'!F9="^", F10="|")), "|", 'Q1.parsed'!G9), 'Q1.parsed'!G9) -> . | H11: =IF('Q1.parsed'!H9=".", IF(OR(H10="|", AND('Q1.parsed'!I9="^", I10="|"), AND('Q1.parsed'!G9="^", G10="|")), "|", 'Q1.parsed'!H9), 'Q1.parsed'!H9) -> . | I11: =IF('Q1.parsed'!I9=".", IF(OR(I10="|", AND('Q1.parsed'!J9="^", J10="|"), AND('Q1.parsed'!H9="^", H10="|")), "|", 'Q1.parsed'!I9), 'Q1.parsed'!I9) -> . | ... EL11: =IF('Q1.parsed'!EL9=".", IF(OR(EL10="|", AND('Q1.parsed'!EM9="^", EM10="|"), AND('Q1.parsed'!EK9="^", EK10="|")), "|", 'Q1.parsed'!EL9), 'Q1.parsed'!EL9) -> .
B12: =IF('Q1.parsed'!B10=".", IF(OR(B11="|", AND('Q1.parsed'!C10="^", C11="|"), AND('Q1.parsed'!A10="^", A11="|")), "|", 'Q1.parsed'!B10), 'Q1.parsed'!B10) -> . | C12: =IF('Q1.parsed'!C10=".", IF(OR(C11="|", AND('Q1.parsed'!D10="^", D11="|"), AND('Q1.parsed'!B10="^", B11="|")), "|", 'Q1.parsed'!C10), 'Q1.parsed'!C10) -> . | D12: =IF('Q1.parsed'!D10=".", IF(OR(D11="|", AND('Q1.parsed'!E10="^", E11="|"), AND('Q1.parsed'!C10="^", C11="|")), "|", 'Q1.parsed'!D10), 'Q1.parsed'!D10) -> . | E12: =IF('Q1.parsed'!E10=".", IF(OR(E11="|", AND('Q1.parsed'!F10="^", F11="|"), AND('Q1.parsed'!D10="^", D11="|")), "|", 'Q1.parsed'!E10), 'Q1.parsed'!E10) -> . | F12: =IF('Q1.parsed'!F10=".", IF(OR(F11="|", AND('Q1.parsed'!G10="^", G11="|"), AND('Q1.parsed'!E10="^", E11="|")), "|", 'Q1.parsed'!F10), 'Q1.parsed'!F10) -> . | G12: =IF('Q1.parsed'!G10=".", IF(OR(G11="|", AND('Q1.parsed'!H10="^", H11="|"), AND('Q1.parsed'!F10="^", F11="|")), "|", 'Q1.parsed'!G10), 'Q1.parsed'!G10) -> . | H12: =IF('Q1.parsed'!H10=".", IF(OR(H11="|", AND('Q1.parsed'!I10="^", I11="|"), AND('Q1.parsed'!G10="^", G11="|")), "|", 'Q1.parsed'!H10), 'Q1.parsed'!H10) -> . | I12: =IF('Q1.parsed'!I10=".", IF(OR(I11="|", AND('Q1.parsed'!J10="^", J11="|"), AND('Q1.parsed'!H10="^", H11="|")), "|", 'Q1.parsed'!I10), 'Q1.parsed'!I10) -> . | ... EL12: =IF('Q1.parsed'!EL10=".", IF(OR(EL11="|", AND('Q1.parsed'!EM10="^", EM11="|"), AND('Q1.parsed'!EK10="^", EK11="|")), "|", 'Q1.parsed'!EL10), 'Q1.parsed'!EL10) -> .
B13: =IF('Q1.parsed'!B11=".", IF(OR(B12="|", AND('Q1.parsed'!C11="^", C12="|"), AND('Q1.parsed'!A11="^", A12="|")), "|", 'Q1.parsed'!B11), 'Q1.parsed'!B11) -> . | C13: =IF('Q1.parsed'!C11=".", IF(OR(C12="|", AND('Q1.parsed'!D11="^", D12="|"), AND('Q1.parsed'!B11="^", B12="|")), "|", 'Q1.parsed'!C11), 'Q1.parsed'!C11) -> . | D13: =IF('Q1.parsed'!D11=".", IF(OR(D12="|", AND('Q1.parsed'!E11="^", E12="|"), AND('Q1.parsed'!C11="^", C12="|")), "|", 'Q1.parsed'!D11), 'Q1.parsed'!D11) -> . | E13: =IF('Q1.parsed'!E11=".", IF(OR(E12="|", AND('Q1.parsed'!F11="^", F12="|"), AND('Q1.parsed'!D11="^", D12="|")), "|", 'Q1.parsed'!E11), 'Q1.parsed'!E11) -> . | F13: =IF('Q1.parsed'!F11=".", IF(OR(F12="|", AND('Q1.parsed'!G11="^", G12="|"), AND('Q1.parsed'!E11="^", E12="|")), "|", 'Q1.parsed'!F11), 'Q1.parsed'!F11) -> . | G13: =IF('Q1.parsed'!G11=".", IF(OR(G12="|", AND('Q1.parsed'!H11="^", H12="|"), AND('Q1.parsed'!F11="^", F12="|")), "|", 'Q1.parsed'!G11), 'Q1.parsed'!G11) -> . | H13: =IF('Q1.parsed'!H11=".", IF(OR(H12="|", AND('Q1.parsed'!I11="^", I12="|"), AND('Q1.parsed'!G11="^", G12="|")), "|", 'Q1.parsed'!H11), 'Q1.parsed'!H11) -> . | I13: =IF('Q1.parsed'!I11=".", IF(OR(I12="|", AND('Q1.parsed'!J11="^", J12="|"), AND('Q1.parsed'!H11="^", H12="|")), "|", 'Q1.parsed'!I11), 'Q1.parsed'!I11) -> . | ... EL13: =IF('Q1.parsed'!EL11=".", IF(OR(EL12="|", AND('Q1.parsed'!EM11="^", EM12="|"), AND('Q1.parsed'!EK11="^", EK12="|")), "|", 'Q1.parsed'!EL11), 'Q1.parsed'!EL11) -> .
B14: =IF('Q1.parsed'!B12=".", IF(OR(B13="|", AND('Q1.parsed'!C12="^", C13="|"), AND('Q1.parsed'!A12="^", A13="|")), "|", 'Q1.parsed'!B12), 'Q1.parsed'!B12) -> . | C14: =IF('Q1.parsed'!C12=".", IF(OR(C13="|", AND('Q1.parsed'!D12="^", D13="|"), AND('Q1.parsed'!B12="^", B13="|")), "|", 'Q1.parsed'!C12), 'Q1.parsed'!C12) -> . | D14: =IF('Q1.parsed'!D12=".", IF(OR(D13="|", AND('Q1.parsed'!E12="^", E13="|"), AND('Q1.parsed'!C12="^", C13="|")), "|", 'Q1.parsed'!D12), 'Q1.parsed'!D12) -> . | E14: =IF('Q1.parsed'!E12=".", IF(OR(E13="|", AND('Q1.parsed'!F12="^", F13="|"), AND('Q1.parsed'!D12="^", D13="|")), "|", 'Q1.parsed'!E12), 'Q1.parsed'!E12) -> . | F14: =IF('Q1.parsed'!F12=".", IF(OR(F13="|", AND('Q1.parsed'!G12="^", G13="|"), AND('Q1.parsed'!E12="^", E13="|")), "|", 'Q1.parsed'!F12), 'Q1.parsed'!F12) -> . | G14: =IF('Q1.parsed'!G12=".", IF(OR(G13="|", AND('Q1.parsed'!H12="^", H13="|"), AND('Q1.parsed'!F12="^", F13="|")), "|", 'Q1.parsed'!G12), 'Q1.parsed'!G12) -> . | H14: =IF('Q1.parsed'!H12=".", IF(OR(H13="|", AND('Q1.parsed'!I12="^", I13="|"), AND('Q1.parsed'!G12="^", G13="|")), "|", 'Q1.parsed'!H12), 'Q1.parsed'!H12) -> . | I14: =IF('Q1.parsed'!I12=".", IF(OR(I13="|", AND('Q1.parsed'!J12="^", J13="|"), AND('Q1.parsed'!H12="^", H13="|")), "|", 'Q1.parsed'!I12), 'Q1.parsed'!I12) -> . | ... EL14: =IF('Q1.parsed'!EL12=".", IF(OR(EL13="|", AND('Q1.parsed'!EM12="^", EM13="|"), AND('Q1.parsed'!EK12="^", EK13="|")), "|", 'Q1.parsed'!EL12), 'Q1.parsed'!EL12) -> .
B15: =IF('Q1.parsed'!B13=".", IF(OR(B14="|", AND('Q1.parsed'!C13="^", C14="|"), AND('Q1.parsed'!A13="^", A14="|")), "|", 'Q1.parsed'!B13), 'Q1.parsed'!B13) -> . | C15: =IF('Q1.parsed'!C13=".", IF(OR(C14="|", AND('Q1.parsed'!D13="^", D14="|"), AND('Q1.parsed'!B13="^", B14="|")), "|", 'Q1.parsed'!C13), 'Q1.parsed'!C13) -> . | D15: =IF('Q1.parsed'!D13=".", IF(OR(D14="|", AND('Q1.parsed'!E13="^", E14="|"), AND('Q1.parsed'!C13="^", C14="|")), "|", 'Q1.parsed'!D13), 'Q1.parsed'!D13) -> . | E15: =IF('Q1.parsed'!E13=".", IF(OR(E14="|", AND('Q1.parsed'!F13="^", F14="|"), AND('Q1.parsed'!D13="^", D14="|")), "|", 'Q1.parsed'!E13), 'Q1.parsed'!E13) -> . | F15: =IF('Q1.parsed'!F13=".", IF(OR(F14="|", AND('Q1.parsed'!G13="^", G14="|"), AND('Q1.parsed'!E13="^", E14="|")), "|", 'Q1.parsed'!F13), 'Q1.parsed'!F13) -> . | G15: =IF('Q1.parsed'!G13=".", IF(OR(G14="|", AND('Q1.parsed'!H13="^", H14="|"), AND('Q1.parsed'!F13="^", F14="|")), "|", 'Q1.parsed'!G13), 'Q1.parsed'!G13) -> . | H15: =IF('Q1.parsed'!H13=".", IF(OR(H14="|", AND('Q1.parsed'!I13="^", I14="|"), AND('Q1.parsed'!G13="^", G14="|")), "|", 'Q1.parsed'!H13), 'Q1.parsed'!H13) -> . | I15: =IF('Q1.parsed'!I13=".", IF(OR(I14="|", AND('Q1.parsed'!J13="^", J14="|"), AND('Q1.parsed'!H13="^", H14="|")), "|", 'Q1.parsed'!I13), 'Q1.parsed'!I13) -> . | ... EL15: =IF('Q1.parsed'!EL13=".", IF(OR(EL14="|", AND('Q1.parsed'!EM13="^", EM14="|"), AND('Q1.parsed'!EK13="^", EK14="|")), "|", 'Q1.parsed'!EL13), 'Q1.parsed'!EL13) -> .
... B145: =IF('Q1.parsed'!B143=".", IF(OR(B144="|", AND('Q1.parsed'!C143="^", C144="|"), AND('Q1.parsed'!A143="^", A144="|")), "|", 'Q1.parsed'!B143), 'Q1.parsed'!B143) -> | | C145: =IF('Q1.parsed'!C143=".", IF(OR(C144="|", AND('Q1.parsed'!D143="^", D144="|"), AND('Q1.parsed'!B143="^", B144="|")), "|", 'Q1.parsed'!C143), 'Q1.parsed'!C143) -> . | D145: =IF('Q1.parsed'!D143=".", IF(OR(D144="|", AND('Q1.parsed'!E143="^", E144="|"), AND('Q1.parsed'!C143="^", C144="|")), "|", 'Q1.parsed'!D143), 'Q1.parsed'!D143) -> | | E145: =IF('Q1.parsed'!E143=".", IF(OR(E144="|", AND('Q1.parsed'!F143="^", F144="|"), AND('Q1.parsed'!D143="^", D144="|")), "|", 'Q1.parsed'!E143), 'Q1.parsed'!E143) -> . | F145: =IF('Q1.parsed'!F143=".", IF(OR(F144="|", AND('Q1.parsed'!G143="^", G144="|"), AND('Q1.parsed'!E143="^", E144="|")), "|", 'Q1.parsed'!F143), 'Q1.parsed'!F143) -> | | G145: =IF('Q1.parsed'!G143=".", IF(OR(G144="|", AND('Q1.parsed'!H143="^", H144="|"), AND('Q1.parsed'!F143="^", F144="|")), "|", 'Q1.parsed'!G143), 'Q1.parsed'!G143) -> | | H145: =IF('Q1.parsed'!H143=".", IF(OR(H144="|", AND('Q1.parsed'!I143="^", I144="|"), AND('Q1.parsed'!G143="^", G144="|")), "|", 'Q1.parsed'!H143), 'Q1.parsed'!H143) -> | | I145: =IF('Q1.parsed'!I143=".", IF(OR(I144="|", AND('Q1.parsed'!J143="^", J144="|"), AND('Q1.parsed'!H143="^", H144="|")), "|", 'Q1.parsed'!I143), 'Q1.parsed'!I143) -> . | ... EL145: =IF('Q1.parsed'!EL143=".", IF(OR(EL144="|", AND('Q1.parsed'!EM143="^", EM144="|"), AND('Q1.parsed'!EK143="^", EK144="|")), "|", 'Q1.parsed'!EL143), 'Q1.parsed'!EL143) -> |

Sheet Q1A
A1: =AND('Q1.splits'!B4="|", 'Q1.splits'!B5="^") -> FALSE | B1: =AND('Q1.splits'!C4="|", 'Q1.splits'!C5="^") -> FALSE | C1: =AND('Q1.splits'!D4="|", 'Q1.splits'!D5="^") -> FALSE | D1: =AND('Q1.splits'!E4="|", 'Q1.splits'!E5="^") -> FALSE | E1: =AND('Q1.splits'!F4="|", 'Q1.splits'!F5="^") -> FALSE | F1: =AND('Q1.splits'!G4="|", 'Q1.splits'!G5="^") -> FALSE | G1: =AND('Q1.splits'!H4="|", 'Q1.splits'!H5="^") -> FALSE | H1: =AND('Q1.splits'!I4="|", 'Q1.splits'!I5="^") -> FALSE | ... EM1: =AND('Q1.splits'!EN4="|", 'Q1.splits'!EN5="^") -> FALSE
A2: =AND('Q1.splits'!B5="|", 'Q1.splits'!B6="^") -> FALSE | B2: =AND('Q1.splits'!C5="|", 'Q1.splits'!C6="^") -> FALSE | C2: =AND('Q1.splits'!D5="|", 'Q1.splits'!D6="^") -> FALSE | D2: =AND('Q1.splits'!E5="|", 'Q1.splits'!E6="^") -> FALSE | E2: =AND('Q1.splits'!F5="|", 'Q1.splits'!F6="^") -> FALSE | F2: =AND('Q1.splits'!G5="|", 'Q1.splits'!G6="^") -> FALSE | G2: =AND('Q1.splits'!H5="|", 'Q1.splits'!H6="^") -> FALSE | H2: =AND('Q1.splits'!I5="|", 'Q1.splits'!I6="^") -> FALSE | ... EM2: =AND('Q1.splits'!EN5="|", 'Q1.splits'!EN6="^") -> FALSE
A3: =AND('Q1.splits'!B6="|", 'Q1.splits'!B7="^") -> FALSE | B3: =AND('Q1.splits'!C6="|", 'Q1.splits'!C7="^") -> FALSE | C3: =AND('Q1.splits'!D6="|", 'Q1.splits'!D7="^") -> FALSE | D3: =AND('Q1.splits'!E6="|", 'Q1.splits'!E7="^") -> FALSE | E3: =AND('Q1.splits'!F6="|", 'Q1.splits'!F7="^") -> FALSE | F3: =AND('Q1.splits'!G6="|", 'Q1.splits'!G7="^") -> FALSE | G3: =AND('Q1.splits'!H6="|", 'Q1.splits'!H7="^") -> FALSE | H3: =AND('Q1.splits'!I6="|", 'Q1.splits'!I7="^") -> FALSE | ... EM3: =AND('Q1.splits'!EN6="|", 'Q1.splits'!EN7="^") -> FALSE
A4: =AND('Q1.splits'!B7="|", 'Q1.splits'!B8="^") -> FALSE | B4: =AND('Q1.splits'!C7="|", 'Q1.splits'!C8="^") -> FALSE | C4: =AND('Q1.splits'!D7="|", 'Q1.splits'!D8="^") -> FALSE | D4: =AND('Q1.splits'!E7="|", 'Q1.splits'!E8="^") -> FALSE | E4: =AND('Q1.splits'!F7="|", 'Q1.splits'!F8="^") -> FALSE | F4: =AND('Q1.splits'!G7="|", 'Q1.splits'!G8="^") -> FALSE | G4: =AND('Q1.splits'!H7="|", 'Q1.splits'!H8="^") -> FALSE | H4: =AND('Q1.splits'!I7="|", 'Q1.splits'!I8="^") -> FALSE | ... EM4: =AND('Q1.splits'!EN7="|", 'Q1.splits'!EN8="^") -> FALSE
A5: =AND('Q1.splits'!B8="|", 'Q1.splits'!B9="^") -> FALSE | B5: =AND('Q1.splits'!C8="|", 'Q1.splits'!C9="^") -> FALSE | C5: =AND('Q1.splits'!D8="|", 'Q1.splits'!D9="^") -> FALSE | D5: =AND('Q1.splits'!E8="|", 'Q1.splits'!E9="^") -> FALSE | E5: =AND('Q1.splits'!F8="|", 'Q1.splits'!F9="^") -> FALSE | F5: =AND('Q1.splits'!G8="|", 'Q1.splits'!G9="^") -> FALSE | G5: =AND('Q1.splits'!H8="|", 'Q1.splits'!H9="^") -> FALSE | H5: =AND('Q1.splits'!I8="|", 'Q1.splits'!I9="^") -> FALSE | ... EM5: =AND('Q1.splits'!EN8="|", 'Q1.splits'!EN9="^") -> FALSE
A6: =AND('Q1.splits'!B9="|", 'Q1.splits'!B10="^") -> FALSE | B6: =AND('Q1.splits'!C9="|", 'Q1.splits'!C10="^") -> FALSE | C6: =AND('Q1.splits'!D9="|", 'Q1.splits'!D10="^") -> FALSE | D6: =AND('Q1.splits'!E9="|", 'Q1.splits'!E10="^") -> FALSE | E6: =AND('Q1.splits'!F9="|", 'Q1.splits'!F10="^") -> FALSE | F6: =AND('Q1.splits'!G9="|", 'Q1.splits'!G10="^") -> FALSE | G6: =AND('Q1.splits'!H9="|", 'Q1.splits'!H10="^") -> FALSE | H6: =AND('Q1.splits'!I9="|", 'Q1.splits'!I10="^") -> FALSE | ... EM6: =AND('Q1.splits'!EN9="|", 'Q1.splits'!EN10="^") -> FALSE
A7: =AND('Q1.splits'!B10="|", 'Q1.splits'!B11="^") -> FALSE | B7: =AND('Q1.splits'!C10="|", 'Q1.splits'!C11="^") -> FALSE | C7: =AND('Q1.splits'!D10="|", 'Q1.splits'!D11="^") -> FALSE | D7: =AND('Q1.splits'!E10="|", 'Q1.splits'!E11="^") -> FALSE | E7: =AND('Q1.splits'!F10="|", 'Q1.splits'!F11="^") -> FALSE | F7: =AND('Q1.splits'!G10="|", 'Q1.splits'!G11="^") -> FALSE | G7: =AND('Q1.splits'!H10="|", 'Q1.splits'!H11="^") -> FALSE | H7: =AND('Q1.splits'!I10="|", 'Q1.splits'!I11="^") -> FALSE | ... EM7: =AND('Q1.splits'!EN10="|", 'Q1.splits'!EN11="^") -> FALSE
A8: =AND('Q1.splits'!B11="|", 'Q1.splits'!B12="^") -> FALSE | B8: =AND('Q1.splits'!C11="|", 'Q1.splits'!C12="^") -> FALSE | C8: =AND('Q1.splits'!D11="|", 'Q1.splits'!D12="^") -> FALSE | D8: =AND('Q1.splits'!E11="|", 'Q1.splits'!E12="^") -> FALSE | E8: =AND('Q1.splits'!F11="|", 'Q1.splits'!F12="^") -> FALSE | F8: =AND('Q1.splits'!G11="|", 'Q1.splits'!G12="^") -> FALSE | G8: =AND('Q1.splits'!H11="|", 'Q1.splits'!H12="^") -> FALSE | H8: =AND('Q1.splits'!I11="|", 'Q1.splits'!I12="^") -> FALSE | ... EM8: =AND('Q1.splits'!EN11="|", 'Q1.splits'!EN12="^") -> FALSE
A9: =AND('Q1.splits'!B12="|", 'Q1.splits'!B13="^") -> FALSE | B9: =AND('Q1.splits'!C12="|", 'Q1.splits'!C13="^") -> FALSE | C9: =AND('Q1.splits'!D12="|", 'Q1.splits'!D13="^") -> FALSE | D9: =AND('Q1.splits'!E12="|", 'Q1.splits'!E13="^") -> FALSE | E9: =AND('Q1.splits'!F12="|", 'Q1.splits'!F13="^") -> FALSE | F9: =AND('Q1.splits'!G12="|", 'Q1.splits'!G13="^") -> FALSE | G9: =AND('Q1.splits'!H12="|", 'Q1.splits'!H13="^") -> FALSE | H9: =AND('Q1.splits'!I12="|", 'Q1.splits'!I13="^") -> FALSE | ... EM9: =AND('Q1.splits'!EN12="|", 'Q1.splits'!EN13="^") -> FALSE
A10: =AND('Q1.splits'!B13="|", 'Q1.splits'!B14="^") -> FALSE | B10: =AND('Q1.splits'!C13="|", 'Q1.splits'!C14="^") -> FALSE | C10: =AND('Q1.splits'!D13="|", 'Q1.splits'!D14="^") -> FALSE | D10: =AND('Q1.splits'!E13="|", 'Q1.splits'!E14="^") -> FALSE | E10: =AND('Q1.splits'!F13="|", 'Q1.splits'!F14="^") -> FALSE | F10: =AND('Q1.splits'!G13="|", 'Q1.splits'!G14="^") -> FALSE | G10: =AND('Q1.splits'!H13="|", 'Q1.splits'!H14="^") -> FALSE | H10: =AND('Q1.splits'!I13="|", 'Q1.splits'!I14="^") -> FALSE | ... EM10: =AND('Q1.splits'!EN13="|", 'Q1.splits'!EN14="^") -> FALSE
A11: =AND('Q1.splits'!B14="|", 'Q1.splits'!B15="^") -> FALSE | B11: =AND('Q1.splits'!C14="|", 'Q1.splits'!C15="^") -> FALSE | C11: =AND('Q1.splits'!D14="|", 'Q1.splits'!D15="^") -> FALSE | D11: =AND('Q1.splits'!E14="|", 'Q1.splits'!E15="^") -> FALSE | E11: =AND('Q1.splits'!F14="|", 'Q1.splits'!F15="^") -> FALSE | F11: =AND('Q1.splits'!G14="|", 'Q1.splits'!G15="^") -> FALSE | G11: =AND('Q1.splits'!H14="|", 'Q1.splits'!H15="^") -> FALSE | H11: =AND('Q1.splits'!I14="|", 'Q1.splits'!I15="^") -> FALSE | ... EM11: =AND('Q1.splits'!EN14="|", 'Q1.splits'!EN15="^") -> FALSE
A12: =AND('Q1.splits'!B15="|", 'Q1.splits'!B16="^") -> FALSE | B12: =AND('Q1.splits'!C15="|", 'Q1.splits'!C16="^") -> FALSE | C12: =AND('Q1.splits'!D15="|", 'Q1.splits'!D16="^") -> FALSE | D12: =AND('Q1.splits'!E15="|", 'Q1.splits'!E16="^") -> FALSE | E12: =AND('Q1.splits'!F15="|", 'Q1.splits'!F16="^") -> FALSE | F12: =AND('Q1.splits'!G15="|", 'Q1.splits'!G16="^") -> FALSE | G12: =AND('Q1.splits'!H15="|", 'Q1.splits'!H16="^") -> FALSE | H12: =AND('Q1.splits'!I15="|", 'Q1.splits'!I16="^") -> FALSE | ... EM12: =AND('Q1.splits'!EN15="|", 'Q1.splits'!EN16="^") -> FALSE
... A153: =AND('Q1.splits'!B156="|", 'Q1.splits'!B157="^") -> FALSE | B153: =AND('Q1.splits'!C156="|", 'Q1.splits'!C157="^") -> FALSE | C153: =AND('Q1.splits'!D156="|", 'Q1.splits'!D157="^") -> FALSE | D153: =AND('Q1.splits'!E156="|", 'Q1.splits'!E157="^") -> FALSE | E153: =AND('Q1.splits'!F156="|", 'Q1.splits'!F157="^") -> FALSE | F153: =AND('Q1.splits'!G156="|", 'Q1.splits'!G157="^") -> FALSE | G153: =AND('Q1.splits'!H156="|", 'Q1.splits'!H157="^") -> FALSE | H153: =AND('Q1.splits'!I156="|", 'Q1.splits'!I157="^") -> FALSE | ... EM153: =AND('Q1.splits'!EN156="|", 'Q1.splits'!EN157="^") -> FALSE
A154: =COUNTIF(A1:EM153, TRUE) -> 1562

Sheet Q2.parsed
B1: 1 | C1: 2 | D1: 3 | E1: 4 | F1: 5 | G1: 6 | H1: 7 | I1: 8 | J1: 9 | K1: 10 | L1: 11 | M1: 12 | N1: 13 | O1: 14 | P1: 15 | Q1: 16 | R1: 17 | S1: 18 | T1: 19 | U1: 20 | V1: 21 | W1: 22 | X1: 23 | Y1: 24 | Z1: 25 | AA1: 26 | AB1: 27 | AC1: 28 | AD1: 29 | AE1: 30 | AF1: 31 | AG1: 32 | AH1: 33 | AI1: 34 | AJ1: 35 | AK1: 36 | AL1: 37 | AM1: 38 | AN1: 39 | AO1: 40 | AP1: 41 | AQ1: 42 | AR1: 43 | AS1: 44 | AT1: 45 | AU1: 46 | AV1: 47 | AW1: 48 | AX1: 49 | AY1: 50 | AZ1: 51 | BA1: 52 | BB1: 53 | BC1: 54 | BD1: 55 | BE1: 56 | BF1: 57 | BG1: 58 | BH1: 59 | BI1: 60 | BJ1: 61 | BK1: 62 | BL1: 63 | BM1: 64 | BN1: 65 | BO1: 66 | BP1: 67 | BQ1: 68 | BR1: 69 | BS1: 70 | BT1: 71 | BU1: 72 | BV1: 73 | BW1: 74 | BX1: 75 | BY1: 76 | BZ1: 77 | CA1: 78 | CB1: 79 | CC1: 80 | CD1: 81 | CE1: 82 | CF1: 83 | CG1: 84 | CH1: 85 | CI1: 86 | CJ1: 87 | CK1: 88 | CL1: 89 | CM1: 90 | CN1: 91 | CO1: 92 | CP1: 93 | CQ1: 94 | CR1: 95 | CS1: 96 | CT1: 97 | CU1: 98 | CV1: 99 | CW1: 100 | CX1: 101 | CY1: 102 | CZ1: 103 | DA1: 104 | DB1: 105 | DC1: 106 | DD1: 107 | DE1: 108 | DF1: 109 | DG1: 110 | DH1: 111 | DI1: 112 | DJ1: 113 | DK1: 114 | DL1: 115 | DM1: 116 | DN1: 117 | DO1: 118 | DP1: 119 | DQ1: 120 | DR1: 121 | DS1: 122 | DT1: 123 | DU1: 124 | DV1: 125 | DW1: 126 | DX1: 127 | DY1: 128 | DZ1: 129 | EA1: 130 | EB1: 131 | EC1: 132 | ED1: 133 | EE1: 134 | EF1: 135 | EG1: 136 | EH1: 137 | EI1: 138 | EJ1: 139 | EK1: 140 | EL1: 141
A2: 0 | B2: =IF('Q1.parsed'!B2=".", 0, IF('Q1.parsed'!B2="|", 1, 'Q1.parsed'!B2)) -> 0 | C2: =IF('Q1.parsed'!C2=".", 0, IF('Q1.parsed'!C2="|", 1, 'Q1.parsed'!C2)) -> 0 | D2: =IF('Q1.parsed'!D2=".", 0, IF('Q1.parsed'!D2="|", 1, 'Q1.parsed'!D2)) -> 0 | E2: =IF('Q1.parsed'!E2=".", 0, IF('Q1.parsed'!E2="|", 1, 'Q1.parsed'!E2)) -> 0 | F2: =IF('Q1.parsed'!F2=".", 0, IF('Q1.parsed'!F2="|", 1, 'Q1.parsed'!F2)) -> 0 | G2: =IF('Q1.parsed'!G2=".", 0, IF('Q1.parsed'!G2="|", 1, 'Q1.parsed'!G2)) -> 0 | H2: =IF('Q1.parsed'!H2=".", 0, IF('Q1.parsed'!H2="|", 1, 'Q1.parsed'!H2)) -> 0 | I2: =IF('Q1.parsed'!I2=".", 0, IF('Q1.parsed'!I2="|", 1, 'Q1.parsed'!I2)) -> 0 | ... EL2: =IF('Q1.parsed'!EL2=".", 0, IF('Q1.parsed'!EL2="|", 1, 'Q1.parsed'!EL2)) -> 0 | EM2: 0
A3: 0 | B3: =IF('Q1.parsed'!B3=".", 0, IF('Q1.parsed'!B3="|", 1, 'Q1.parsed'!B3)) -> 0 | C3: =IF('Q1.parsed'!C3=".", 0, IF('Q1.parsed'!C3="|", 1, 'Q1.parsed'!C3)) -> 0 | D3: =IF('Q1.parsed'!D3=".", 0, IF('Q1.parsed'!D3="|", 1, 'Q1.parsed'!D3)) -> 0 | E3: =IF('Q1.parsed'!E3=".", 0, IF('Q1.parsed'!E3="|", 1, 'Q1.parsed'!E3)) -> 0 | F3: =IF('Q1.parsed'!F3=".", 0, IF('Q1.parsed'!F3="|", 1, 'Q1.parsed'!F3)) -> 0 | G3: =IF('Q1.parsed'!G3=".", 0, IF('Q1.parsed'!G3="|", 1, 'Q1.parsed'!G3)) -> 0 | H3: =IF('Q1.parsed'!H3=".", 0, IF('Q1.parsed'!H3="|", 1, 'Q1.parsed'!H3)) -> 0 | I3: =IF('Q1.parsed'!I3=".", 0, IF('Q1.parsed'!I3="|", 1, 'Q1.parsed'!I3)) -> 0 | ... EL3: =IF('Q1.parsed'!EL3=".", 0, IF('Q1.parsed'!EL3="|", 1, 'Q1.parsed'!EL3)) -> 0 | EM3: 0
A4: 0 | B4: =IF('Q1.parsed'!B4=".", 0, IF('Q1.parsed'!B4="|", 1, 'Q1.parsed'!B4)) -> 0 | C4: =IF('Q1.parsed'!C4=".", 0, IF('Q1.parsed'!C4="|", 1, 'Q1.parsed'!C4)) -> 0 | D4: =IF('Q1.parsed'!D4=".", 0, IF('Q1.parsed'!D4="|", 1, 'Q1.parsed'!D4)) -> 0 | E4: =IF('Q1.parsed'!E4=".", 0, IF('Q1.parsed'!E4="|", 1, 'Q1.parsed'!E4)) -> 0 | F4: =IF('Q1.parsed'!F4=".", 0, IF('Q1.parsed'!F4="|", 1, 'Q1.parsed'!F4)) -> 0 | G4: =IF('Q1.parsed'!G4=".", 0, IF('Q1.parsed'!G4="|", 1, 'Q1.parsed'!G4)) -> 0 | H4: =IF('Q1.parsed'!H4=".", 0, IF('Q1.parsed'!H4="|", 1, 'Q1.parsed'!H4)) -> 0 | I4: =IF('Q1.parsed'!I4=".", 0, IF('Q1.parsed'!I4="|", 1, 'Q1.parsed'!I4)) -> 0 | ... EL4: =IF('Q1.parsed'!EL4=".", 0, IF('Q1.parsed'!EL4="|", 1, 'Q1.parsed'!EL4)) -> 0 | EM4: 0
A5: 0 | B5: =IF('Q1.parsed'!B5=".", 0, IF('Q1.parsed'!B5="|", 1, 'Q1.parsed'!B5)) -> 0 | C5: =IF('Q1.parsed'!C5=".", 0, IF('Q1.parsed'!C5="|", 1, 'Q1.parsed'!C5)) -> 0 | D5: =IF('Q1.parsed'!D5=".", 0, IF('Q1.parsed'!D5="|", 1, 'Q1.parsed'!D5)) -> 0 | E5: =IF('Q1.parsed'!E5=".", 0, IF('Q1.parsed'!E5="|", 1, 'Q1.parsed'!E5)) -> 0 | F5: =IF('Q1.parsed'!F5=".", 0, IF('Q1.parsed'!F5="|", 1, 'Q1.parsed'!F5)) -> 0 | G5: =IF('Q1.parsed'!G5=".", 0, IF('Q1.parsed'!G5="|", 1, 'Q1.parsed'!G5)) -> 0 | H5: =IF('Q1.parsed'!H5=".", 0, IF('Q1.parsed'!H5="|", 1, 'Q1.parsed'!H5)) -> 0 | I5: =IF('Q1.parsed'!I5=".", 0, IF('Q1.parsed'!I5="|", 1, 'Q1.parsed'!I5)) -> 0 | ... EL5: =IF('Q1.parsed'!EL5=".", 0, IF('Q1.parsed'!EL5="|", 1, 'Q1.parsed'!EL5)) -> 0 | EM5: 0
A6: 0 | B6: =IF('Q1.parsed'!B6=".", 0, IF('Q1.parsed'!B6="|", 1, 'Q1.parsed'!B6)) -> 0 | C6: =IF('Q1.parsed'!C6=".", 0, IF('Q1.parsed'!C6="|", 1, 'Q1.parsed'!C6)) -> 0 | D6: =IF('Q1.parsed'!D6=".", 0, IF('Q1.parsed'!D6="|", 1, 'Q1.parsed'!D6)) -> 0 | E6: =IF('Q1.parsed'!E6=".", 0, IF('Q1.parsed'!E6="|", 1, 'Q1.parsed'!E6)) -> 0 | F6: =IF('Q1.parsed'!F6=".", 0, IF('Q1.parsed'!F6="|", 1, 'Q1.parsed'!F6)) -> 0 | G6: =IF('Q1.parsed'!G6=".", 0, IF('Q1.parsed'!G6="|", 1, 'Q1.parsed'!G6)) -> 0 | H6: =IF('Q1.parsed'!H6=".", 0, IF('Q1.parsed'!H6="|", 1, 'Q1.parsed'!H6)) -> 0 | I6: =IF('Q1.parsed'!I6=".", 0, IF('Q1.parsed'!I6="|", 1, 'Q1.parsed'!I6)) -> 0 | ... EL6: =IF('Q1.parsed'!EL6=".", 0, IF('Q1.parsed'!EL6="|", 1, 'Q1.parsed'!EL6)) -> 0 | EM6: 0
A7: 0 | B7: =IF('Q1.parsed'!B7=".", 0, IF('Q1.parsed'!B7="|", 1, 'Q1.parsed'!B7)) -> 0 | C7: =IF('Q1.parsed'!C7=".", 0, IF('Q1.parsed'!C7="|", 1, 'Q1.parsed'!C7)) -> 0 | D7: =IF('Q1.parsed'!D7=".", 0, IF('Q1.parsed'!D7="|", 1, 'Q1.parsed'!D7)) -> 0 | E7: =IF('Q1.parsed'!E7=".", 0, IF('Q1.parsed'!E7="|", 1, 'Q1.parsed'!E7)) -> 0 | F7: =IF('Q1.parsed'!F7=".", 0, IF('Q1.parsed'!F7="|", 1, 'Q1.parsed'!F7)) -> 0 | G7: =IF('Q1.parsed'!G7=".", 0, IF('Q1.parsed'!G7="|", 1, 'Q1.parsed'!G7)) -> 0 | H7: =IF('Q1.parsed'!H7=".", 0, IF('Q1.parsed'!H7="|", 1, 'Q1.parsed'!H7)) -> 0 | I7: =IF('Q1.parsed'!I7=".", 0, IF('Q1.parsed'!I7="|", 1, 'Q1.parsed'!I7)) -> 0 | ... EL7: =IF('Q1.parsed'!EL7=".", 0, IF('Q1.parsed'!EL7="|", 1, 'Q1.parsed'!EL7)) -> 0 | EM7: 0
A8: 0 | B8: =IF('Q1.parsed'!B8=".", 0, IF('Q1.parsed'!B8="|", 1, 'Q1.parsed'!B8)) -> 0 | C8: =IF('Q1.parsed'!C8=".", 0, IF('Q1.parsed'!C8="|", 1, 'Q1.parsed'!C8)) -> 0 | D8: =IF('Q1.parsed'!D8=".", 0, IF('Q1.parsed'!D8="|", 1, 'Q1.parsed'!D8)) -> 0 | E8: =IF('Q1.parsed'!E8=".", 0, IF('Q1.parsed'!E8="|", 1, 'Q1.parsed'!E8)) -> 0 | F8: =IF('Q1.parsed'!F8=".", 0, IF('Q1.parsed'!F8="|", 1, 'Q1.parsed'!F8)) -> 0 | G8: =IF('Q1.parsed'!G8=".", 0, IF('Q1.parsed'!G8="|", 1, 'Q1.parsed'!G8)) -> 0 | H8: =IF('Q1.parsed'!H8=".", 0, IF('Q1.parsed'!H8="|", 1, 'Q1.parsed'!H8)) -> 0 | I8: =IF('Q1.parsed'!I8=".", 0, IF('Q1.parsed'!I8="|", 1, 'Q1.parsed'!I8)) -> 0 | ... EL8: =IF('Q1.parsed'!EL8=".", 0, IF('Q1.parsed'!EL8="|", 1, 'Q1.parsed'!EL8)) -> 0 | EM8: 0
A9: 0 | B9: =IF('Q1.parsed'!B9=".", 0, IF('Q1.parsed'!B9="|", 1, 'Q1.parsed'!B9)) -> 0 | C9: =IF('Q1.parsed'!C9=".", 0, IF('Q1.parsed'!C9="|", 1, 'Q1.parsed'!C9)) -> 0 | D9: =IF('Q1.parsed'!D9=".", 0, IF('Q1.parsed'!D9="|", 1, 'Q1.parsed'!D9)) -> 0 | E9: =IF('Q1.parsed'!E9=".", 0, IF('Q1.parsed'!E9="|", 1, 'Q1.parsed'!E9)) -> 0 | F9: =IF('Q1.parsed'!F9=".", 0, IF('Q1.parsed'!F9="|", 1, 'Q1.parsed'!F9)) -> 0 | G9: =IF('Q1.parsed'!G9=".", 0, IF('Q1.parsed'!G9="|", 1, 'Q1.parsed'!G9)) -> 0 | H9: =IF('Q1.parsed'!H9=".", 0, IF('Q1.parsed'!H9="|", 1, 'Q1.parsed'!H9)) -> 0 | I9: =IF('Q1.parsed'!I9=".", 0, IF('Q1.parsed'!I9="|", 1, 'Q1.parsed'!I9)) -> 0 | ... EL9: =IF('Q1.parsed'!EL9=".", 0, IF('Q1.parsed'!EL9="|", 1, 'Q1.parsed'!EL9)) -> 0 | EM9: 0
A10: 0 | B10: =IF('Q1.parsed'!B10=".", 0, IF('Q1.parsed'!B10="|", 1, 'Q1.parsed'!B10)) -> 0 | C10: =IF('Q1.parsed'!C10=".", 0, IF('Q1.parsed'!C10="|", 1, 'Q1.parsed'!C10)) -> 0 | D10: =IF('Q1.parsed'!D10=".", 0, IF('Q1.parsed'!D10="|", 1, 'Q1.parsed'!D10)) -> 0 | E10: =IF('Q1.parsed'!E10=".", 0, IF('Q1.parsed'!E10="|", 1, 'Q1.parsed'!E10)) -> 0 | F10: =IF('Q1.parsed'!F10=".", 0, IF('Q1.parsed'!F10="|", 1, 'Q1.parsed'!F10)) -> 0 | G10: =IF('Q1.parsed'!G10=".", 0, IF('Q1.parsed'!G10="|", 1, 'Q1.parsed'!G10)) -> 0 | H10: =IF('Q1.parsed'!H10=".", 0, IF('Q1.parsed'!H10="|", 1, 'Q1.parsed'!H10)) -> 0 | I10: =IF('Q1.parsed'!I10=".", 0, IF('Q1.parsed'!I10="|", 1, 'Q1.parsed'!I10)) -> 0 | ... EL10: =IF('Q1.parsed'!EL10=".", 0, IF('Q1.parsed'!EL10="|", 1, 'Q1.parsed'!EL10)) -> 0 | EM10: 0
A11: 0 | B11: =IF('Q1.parsed'!B11=".", 0, IF('Q1.parsed'!B11="|", 1, 'Q1.parsed'!B11)) -> 0 | C11: =IF('Q1.parsed'!C11=".", 0, IF('Q1.parsed'!C11="|", 1, 'Q1.parsed'!C11)) -> 0 | D11: =IF('Q1.parsed'!D11=".", 0, IF('Q1.parsed'!D11="|", 1, 'Q1.parsed'!D11)) -> 0 | E11: =IF('Q1.parsed'!E11=".", 0, IF('Q1.parsed'!E11="|", 1, 'Q1.parsed'!E11)) -> 0 | F11: =IF('Q1.parsed'!F11=".", 0, IF('Q1.parsed'!F11="|", 1, 'Q1.parsed'!F11)) -> 0 | G11: =IF('Q1.parsed'!G11=".", 0, IF('Q1.parsed'!G11="|", 1, 'Q1.parsed'!G11)) -> 0 | H11: =IF('Q1.parsed'!H11=".", 0, IF('Q1.parsed'!H11="|", 1, 'Q1.parsed'!H11)) -> 0 | I11: =IF('Q1.parsed'!I11=".", 0, IF('Q1.parsed'!I11="|", 1, 'Q1.parsed'!I11)) -> 0 | ... EL11: =IF('Q1.parsed'!EL11=".", 0, IF('Q1.parsed'!EL11="|", 1, 'Q1.parsed'!EL11)) -> 0 | EM11: 0
A12: 0 | B12: =IF('Q1.parsed'!B12=".", 0, IF('Q1.parsed'!B12="|", 1, 'Q1.parsed'!B12)) -> 0 | C12: =IF('Q1.parsed'!C12=".", 0, IF('Q1.parsed'!C12="|", 1, 'Q1.parsed'!C12)) -> 0 | D12: =IF('Q1.parsed'!D12=".", 0, IF('Q1.parsed'!D12="|", 1, 'Q1.parsed'!D12)) -> 0 | E12: =IF('Q1.parsed'!E12=".", 0, IF('Q1.parsed'!E12="|", 1, 'Q1.parsed'!E12)) -> 0 | F12: =IF('Q1.parsed'!F12=".", 0, IF('Q1.parsed'!F12="|", 1, 'Q1.parsed'!F12)) -> 0 | G12: =IF('Q1.parsed'!G12=".", 0, IF('Q1.parsed'!G12="|", 1, 'Q1.parsed'!G12)) -> 0 | H12: =IF('Q1.parsed'!H12=".", 0, IF('Q1.parsed'!H12="|", 1, 'Q1.parsed'!H12)) -> 0 | I12: =IF('Q1.parsed'!I12=".", 0, IF('Q1.parsed'!I12="|", 1, 'Q1.parsed'!I12)) -> 0 | ... EL12: =IF('Q1.parsed'!EL12=".", 0, IF('Q1.parsed'!EL12="|", 1, 'Q1.parsed'!EL12)) -> 0 | EM12: 0
A13: 0 | B13: =IF('Q1.parsed'!B13=".", 0, IF('Q1.parsed'!B13="|", 1, 'Q1.parsed'!B13)) -> 0 | C13: =IF('Q1.parsed'!C13=".", 0, IF('Q1.parsed'!C13="|", 1, 'Q1.parsed'!C13)) -> 0 | D13: =IF('Q1.parsed'!D13=".", 0, IF('Q1.parsed'!D13="|", 1, 'Q1.parsed'!D13)) -> 0 | E13: =IF('Q1.parsed'!E13=".", 0, IF('Q1.parsed'!E13="|", 1, 'Q1.parsed'!E13)) -> 0 | F13: =IF('Q1.parsed'!F13=".", 0, IF('Q1.parsed'!F13="|", 1, 'Q1.parsed'!F13)) -> 0 | G13: =IF('Q1.parsed'!G13=".", 0, IF('Q1.parsed'!G13="|", 1, 'Q1.parsed'!G13)) -> 0 | H13: =IF('Q1.parsed'!H13=".", 0, IF('Q1.parsed'!H13="|", 1, 'Q1.parsed'!H13)) -> 0 | I13: =IF('Q1.parsed'!I13=".", 0, IF('Q1.parsed'!I13="|", 1, 'Q1.parsed'!I13)) -> 0 | ... EL13: =IF('Q1.parsed'!EL13=".", 0, IF('Q1.parsed'!EL13="|", 1, 'Q1.parsed'!EL13)) -> 0 | EM13: 0
... A143: 0 | B143: =IF('Q1.parsed'!B143=".", 0, IF('Q1.parsed'!B143="|", 1, 'Q1.parsed'!B143)) -> 0 | C143: =IF('Q1.parsed'!C143=".", 0, IF('Q1.parsed'!C143="|", 1, 'Q1.parsed'!C143)) -> 0 | D143: =IF('Q1.parsed'!D143=".", 0, IF('Q1.parsed'!D143="|", 1, 'Q1.parsed'!D143)) -> 0 | E143: =IF('Q1.parsed'!E143=".", 0, IF('Q1.parsed'!E143="|", 1, 'Q1.parsed'!E143)) -> 0 | F143: =IF('Q1.parsed'!F143=".", 0, IF('Q1.parsed'!F143="|", 1, 'Q1.parsed'!F143)) -> 0 | G143: =IF('Q1.parsed'!G143=".", 0, IF('Q1.parsed'!G143="|", 1, 'Q1.parsed'!G143)) -> 0 | H143: =IF('Q1.parsed'!H143=".", 0, IF('Q1.parsed'!H143="|", 1, 'Q1.parsed'!H143)) -> 0 | I143: =IF('Q1.parsed'!I143=".", 0, IF('Q1.parsed'!I143="|", 1, 'Q1.parsed'!I143)) -> 0 | ... EL143: =IF('Q1.parsed'!EL143=".", 0, IF('Q1.parsed'!EL143="|", 1, 'Q1.parsed'!EL143)) -> 0 | EM143: 0

Sheet Q2.splits
B1: add cell above, if cell right is ^ then right above, if cell left is ^ then left above
B2: If self is . and right is ^ and above right is | or left is ^ and above left is | then |
B3: else
A4: ='Q2.parsed'!A2 -> 0 | B4: ='Q2.parsed'!B2 -> 0 | C4: ='Q2.parsed'!C2 -> 0 | D4: ='Q2.parsed'!D2 -> 0 | E4: ='Q2.parsed'!E2 -> 0 | F4: ='Q2.parsed'!F2 -> 0 | G4: ='Q2.parsed'!G2 -> 0 | H4: ='Q2.parsed'!H2 -> 0 | ... EM4: ='Q2.parsed'!EM2 -> 0
A5: ='Q2.parsed'!A3 -> 0 | B5: =IF('Q2.parsed'!B3="^", 0, IF(ISNUMBER(B4), B4, 0) + IF('Q2.parsed'!A3="^",A4, 0) + IF('Q2.parsed'!C3="^", C4, 0)) -> 0 | C5: =IF('Q2.parsed'!C3="^", 0, IF(ISNUMBER(C4), C4, 0) + IF('Q2.parsed'!B3="^",B4, 0) + IF('Q2.parsed'!D3="^", D4, 0)) -> 0 | D5: =IF('Q2.parsed'!D3="^", 0, IF(ISNUMBER(D4), D4, 0) + IF('Q2.parsed'!C3="^",C4, 0) + IF('Q2.parsed'!E3="^", E4, 0)) -> 0 | E5: =IF('Q2.parsed'!E3="^", 0, IF(ISNUMBER(E4), E4, 0) + IF('Q2.parsed'!D3="^",D4, 0) + IF('Q2.parsed'!F3="^", F4, 0)) -> 0 | F5: =IF('Q2.parsed'!F3="^", 0, IF(ISNUMBER(F4), F4, 0) + IF('Q2.parsed'!E3="^",E4, 0) + IF('Q2.parsed'!G3="^", G4, 0)) -> 0 | G5: =IF('Q2.parsed'!G3="^", 0, IF(ISNUMBER(G4), G4, 0) + IF('Q2.parsed'!F3="^",F4, 0) + IF('Q2.parsed'!H3="^", H4, 0)) -> 0 | H5: =IF('Q2.parsed'!H3="^", 0, IF(ISNUMBER(H4), H4, 0) + IF('Q2.parsed'!G3="^",G4, 0) + IF('Q2.parsed'!I3="^", I4, 0)) -> 0 | I5: =IF('Q2.parsed'!I3="^", 0, IF(ISNUMBER(I4), I4, 0) + IF('Q2.parsed'!H3="^",H4, 0) + IF('Q2.parsed'!J3="^", J4, 0)) -> 0 | ... EL5: =IF('Q2.parsed'!EL3="^", 0, IF(ISNUMBER(EL4), EL4, 0) + IF('Q2.parsed'!EK3="^",EK4, 0) + IF('Q2.parsed'!EM3="^", EM4, 0)) -> 0 | EM5: ='Q2.parsed'!EM3 -> 0
A6: ='Q2.parsed'!A4 -> 0 | B6: =IF('Q2.parsed'!B4="^", 0, IF(ISNUMBER(B5), B5, 0) + IF('Q2.parsed'!A4="^",A5, 0) + IF('Q2.parsed'!C4="^", C5, 0)) -> 0 | C6: =IF('Q2.parsed'!C4="^", 0, IF(ISNUMBER(C5), C5, 0) + IF('Q2.parsed'!B4="^",B5, 0) + IF('Q2.parsed'!D4="^", D5, 0)) -> 0 | D6: =IF('Q2.parsed'!D4="^", 0, IF(ISNUMBER(D5), D5, 0) + IF('Q2.parsed'!C4="^",C5, 0) + IF('Q2.parsed'!E4="^", E5, 0)) -> 0 | E6: =IF('Q2.parsed'!E4="^", 0, IF(ISNUMBER(E5), E5, 0) + IF('Q2.parsed'!D4="^",D5, 0) + IF('Q2.parsed'!F4="^", F5, 0)) -> 0 | F6: =IF('Q2.parsed'!F4="^", 0, IF(ISNUMBER(F5), F5, 0) + IF('Q2.parsed'!E4="^",E5, 0) + IF('Q2.parsed'!G4="^", G5, 0)) -> 0 | G6: =IF('Q2.parsed'!G4="^", 0, IF(ISNUMBER(G5), G5, 0) + IF('Q2.parsed'!F4="^",F5, 0) + IF('Q2.parsed'!H4="^", H5, 0)) -> 0 | H6: =IF('Q2.parsed'!H4="^", 0, IF(ISNUMBER(H5), H5, 0) + IF('Q2.parsed'!G4="^",G5, 0) + IF('Q2.parsed'!I4="^", I5, 0)) -> 0 | I6: =IF('Q2.parsed'!I4="^", 0, IF(ISNUMBER(I5), I5, 0) + IF('Q2.parsed'!H4="^",H5, 0) + IF('Q2.parsed'!J4="^", J5, 0)) -> 0 | ... EL6: =IF('Q2.parsed'!EL4="^", 0, IF(ISNUMBER(EL5), EL5, 0) + IF('Q2.parsed'!EK4="^",EK5, 0) + IF('Q2.parsed'!EM4="^", EM5, 0)) -> 0 | EM6: ='Q2.parsed'!EM4 -> 0
A7: ='Q2.parsed'!A5 -> 0 | B7: =IF('Q2.parsed'!B5="^", 0, IF(ISNUMBER(B6), B6, 0) + IF('Q2.parsed'!A5="^",A6, 0) + IF('Q2.parsed'!C5="^", C6, 0)) -> 0 | C7: =IF('Q2.parsed'!C5="^", 0, IF(ISNUMBER(C6), C6, 0) + IF('Q2.parsed'!B5="^",B6, 0) + IF('Q2.parsed'!D5="^", D6, 0)) -> 0 | D7: =IF('Q2.parsed'!D5="^", 0, IF(ISNUMBER(D6), D6, 0) + IF('Q2.parsed'!C5="^",C6, 0) + IF('Q2.parsed'!E5="^", E6, 0)) -> 0 | E7: =IF('Q2.parsed'!E5="^", 0, IF(ISNUMBER(E6), E6, 0) + IF('Q2.parsed'!D5="^",D6, 0) + IF('Q2.parsed'!F5="^", F6, 0)) -> 0 | F7: =IF('Q2.parsed'!F5="^", 0, IF(ISNUMBER(F6), F6, 0) + IF('Q2.parsed'!E5="^",E6, 0) + IF('Q2.parsed'!G5="^", G6, 0)) -> 0 | G7: =IF('Q2.parsed'!G5="^", 0, IF(ISNUMBER(G6), G6, 0) + IF('Q2.parsed'!F5="^",F6, 0) + IF('Q2.parsed'!H5="^", H6, 0)) -> 0 | H7: =IF('Q2.parsed'!H5="^", 0, IF(ISNUMBER(H6), H6, 0) + IF('Q2.parsed'!G5="^",G6, 0) + IF('Q2.parsed'!I5="^", I6, 0)) -> 0 | I7: =IF('Q2.parsed'!I5="^", 0, IF(ISNUMBER(I6), I6, 0) + IF('Q2.parsed'!H5="^",H6, 0) + IF('Q2.parsed'!J5="^", J6, 0)) -> 0 | ... EL7: =IF('Q2.parsed'!EL5="^", 0, IF(ISNUMBER(EL6), EL6, 0) + IF('Q2.parsed'!EK5="^",EK6, 0) + IF('Q2.parsed'!EM5="^", EM6, 0)) -> 0 | EM7: ='Q2.parsed'!EM5 -> 0
A8: ='Q2.parsed'!A6 -> 0 | B8: =IF('Q2.parsed'!B6="^", 0, IF(ISNUMBER(B7), B7, 0) + IF('Q2.parsed'!A6="^",A7, 0) + IF('Q2.parsed'!C6="^", C7, 0)) -> 0 | C8: =IF('Q2.parsed'!C6="^", 0, IF(ISNUMBER(C7), C7, 0) + IF('Q2.parsed'!B6="^",B7, 0) + IF('Q2.parsed'!D6="^", D7, 0)) -> 0 | D8: =IF('Q2.parsed'!D6="^", 0, IF(ISNUMBER(D7), D7, 0) + IF('Q2.parsed'!C6="^",C7, 0) + IF('Q2.parsed'!E6="^", E7, 0)) -> 0 | E8: =IF('Q2.parsed'!E6="^", 0, IF(ISNUMBER(E7), E7, 0) + IF('Q2.parsed'!D6="^",D7, 0) + IF('Q2.parsed'!F6="^", F7, 0)) -> 0 | F8: =IF('Q2.parsed'!F6="^", 0, IF(ISNUMBER(F7), F7, 0) + IF('Q2.parsed'!E6="^",E7, 0) + IF('Q2.parsed'!G6="^", G7, 0)) -> 0 | G8: =IF('Q2.parsed'!G6="^", 0, IF(ISNUMBER(G7), G7, 0) + IF('Q2.parsed'!F6="^",F7, 0) + IF('Q2.parsed'!H6="^", H7, 0)) -> 0 | H8: =IF('Q2.parsed'!H6="^", 0, IF(ISNUMBER(H7), H7, 0) + IF('Q2.parsed'!G6="^",G7, 0) + IF('Q2.parsed'!I6="^", I7, 0)) -> 0 | I8: =IF('Q2.parsed'!I6="^", 0, IF(ISNUMBER(I7), I7, 0) + IF('Q2.parsed'!H6="^",H7, 0) + IF('Q2.parsed'!J6="^", J7, 0)) -> 0 | ... EL8: =IF('Q2.parsed'!EL6="^", 0, IF(ISNUMBER(EL7), EL7, 0) + IF('Q2.parsed'!EK6="^",EK7, 0) + IF('Q2.parsed'!EM6="^", EM7, 0)) -> 0 | EM8: ='Q2.parsed'!EM6 -> 0
A9: ='Q2.parsed'!A7 -> 0 | B9: =IF('Q2.parsed'!B7="^", 0, IF(ISNUMBER(B8), B8, 0) + IF('Q2.parsed'!A7="^",A8, 0) + IF('Q2.parsed'!C7="^", C8, 0)) -> 0 | C9: =IF('Q2.parsed'!C7="^", 0, IF(ISNUMBER(C8), C8, 0) + IF('Q2.parsed'!B7="^",B8, 0) + IF('Q2.parsed'!D7="^", D8, 0)) -> 0 | D9: =IF('Q2.parsed'!D7="^", 0, IF(ISNUMBER(D8), D8, 0) + IF('Q2.parsed'!C7="^",C8, 0) + IF('Q2.parsed'!E7="^", E8, 0)) -> 0 | E9: =IF('Q2.parsed'!E7="^", 0, IF(ISNUMBER(E8), E8, 0) + IF('Q2.parsed'!D7="^",D8, 0) + IF('Q2.parsed'!F7="^", F8, 0)) -> 0 | F9: =IF('Q2.parsed'!F7="^", 0, IF(ISNUMBER(F8), F8, 0) + IF('Q2.parsed'!E7="^",E8, 0) + IF('Q2.parsed'!G7="^", G8, 0)) -> 0 | G9: =IF('Q2.parsed'!G7="^", 0, IF(ISNUMBER(G8), G8, 0) + IF('Q2.parsed'!F7="^",F8, 0) + IF('Q2.parsed'!H7="^", H8, 0)) -> 0 | H9: =IF('Q2.parsed'!H7="^", 0, IF(ISNUMBER(H8), H8, 0) + IF('Q2.parsed'!G7="^",G8, 0) + IF('Q2.parsed'!I7="^", I8, 0)) -> 0 | I9: =IF('Q2.parsed'!I7="^", 0, IF(ISNUMBER(I8), I8, 0) + IF('Q2.parsed'!H7="^",H8, 0) + IF('Q2.parsed'!J7="^", J8, 0)) -> 0 | ... EL9: =IF('Q2.parsed'!EL7="^", 0, IF(ISNUMBER(EL8), EL8, 0) + IF('Q2.parsed'!EK7="^",EK8, 0) + IF('Q2.parsed'!EM7="^", EM8, 0)) -> 0 | EM9: ='Q2.parsed'!EM7 -> 0
A10: ='Q2.parsed'!A8 -> 0 | B10: =IF('Q2.parsed'!B8="^", 0, IF(ISNUMBER(B9), B9, 0) + IF('Q2.parsed'!A8="^",A9, 0) + IF('Q2.parsed'!C8="^", C9, 0)) -> 0 | C10: =IF('Q2.parsed'!C8="^", 0, IF(ISNUMBER(C9), C9, 0) + IF('Q2.parsed'!B8="^",B9, 0) + IF('Q2.parsed'!D8="^", D9, 0)) -> 0 | D10: =IF('Q2.parsed'!D8="^", 0, IF(ISNUMBER(D9), D9, 0) + IF('Q2.parsed'!C8="^",C9, 0) + IF('Q2.parsed'!E8="^", E9, 0)) -> 0 | E10: =IF('Q2.parsed'!E8="^", 0, IF(ISNUMBER(E9), E9, 0) + IF('Q2.parsed'!D8="^",D9, 0) + IF('Q2.parsed'!F8="^", F9, 0)) -> 0 | F10: =IF('Q2.parsed'!F8="^", 0, IF(ISNUMBER(F9), F9, 0) + IF('Q2.parsed'!E8="^",E9, 0) + IF('Q2.parsed'!G8="^", G9, 0)) -> 0 | G10: =IF('Q2.parsed'!G8="^", 0, IF(ISNUMBER(G9), G9, 0) + IF('Q2.parsed'!F8="^",F9, 0) + IF('Q2.parsed'!H8="^", H9, 0)) -> 0 | H10: =IF('Q2.parsed'!H8="^", 0, IF(ISNUMBER(H9), H9, 0) + IF('Q2.parsed'!G8="^",G9, 0) + IF('Q2.parsed'!I8="^", I9, 0)) -> 0 | I10: =IF('Q2.parsed'!I8="^", 0, IF(ISNUMBER(I9), I9, 0) + IF('Q2.parsed'!H8="^",H9, 0) + IF('Q2.parsed'!J8="^", J9, 0)) -> 0 | ... EL10: =IF('Q2.parsed'!EL8="^", 0, IF(ISNUMBER(EL9), EL9, 0) + IF('Q2.parsed'!EK8="^",EK9, 0) + IF('Q2.parsed'!EM8="^", EM9, 0)) -> 0 | EM10: ='Q2.parsed'!EM8 -> 0
A11: ='Q2.parsed'!A9 -> 0 | B11: =IF('Q2.parsed'!B9="^", 0, IF(ISNUMBER(B10), B10, 0) + IF('Q2.parsed'!A9="^",A10, 0) + IF('Q2.parsed'!C9="^", C10, 0)) -> 0 | C11: =IF('Q2.parsed'!C9="^", 0, IF(ISNUMBER(C10), C10, 0) + IF('Q2.parsed'!B9="^",B10, 0) + IF('Q2.parsed'!D9="^", D10, 0)) -> 0 | D11: =IF('Q2.parsed'!D9="^", 0, IF(ISNUMBER(D10), D10, 0) + IF('Q2.parsed'!C9="^",C10, 0) + IF('Q2.parsed'!E9="^", E10, 0)) -> 0 | E11: =IF('Q2.parsed'!E9="^", 0, IF(ISNUMBER(E10), E10, 0) + IF('Q2.parsed'!D9="^",D10, 0) + IF('Q2.parsed'!F9="^", F10, 0)) -> 0 | F11: =IF('Q2.parsed'!F9="^", 0, IF(ISNUMBER(F10), F10, 0) + IF('Q2.parsed'!E9="^",E10, 0) + IF('Q2.parsed'!G9="^", G10, 0)) -> 0 | G11: =IF('Q2.parsed'!G9="^", 0, IF(ISNUMBER(G10), G10, 0) + IF('Q2.parsed'!F9="^",F10, 0) + IF('Q2.parsed'!H9="^", H10, 0)) -> 0 | H11: =IF('Q2.parsed'!H9="^", 0, IF(ISNUMBER(H10), H10, 0) + IF('Q2.parsed'!G9="^",G10, 0) + IF('Q2.parsed'!I9="^", I10, 0)) -> 0 | I11: =IF('Q2.parsed'!I9="^", 0, IF(ISNUMBER(I10), I10, 0) + IF('Q2.parsed'!H9="^",H10, 0) + IF('Q2.parsed'!J9="^", J10, 0)) -> 0 | ... EL11: =IF('Q2.parsed'!EL9="^", 0, IF(ISNUMBER(EL10), EL10, 0) + IF('Q2.parsed'!EK9="^",EK10, 0) + IF('Q2.parsed'!EM9="^", EM10, 0)) -> 0 | EM11: ='Q2.parsed'!EM9 -> 0
